Workbook
Name IQ_CH: 110000
Name IQ_CQ: 5000
Name IQ_CY: 10000
Name IQ_DAILY: 500000
Name IQ_FH: 100000
Name IQ_FQ: 500
Name IQ_FY: 1000
Name IQ_LTM: 2000
Name IQ_MONTH: 15000
Name IQ_NTM: 6000
Name IQ_WEEK: 50000
Name IQ_YTD: 3000

Sheet COVER
B2: Shopify, Inc. (SHOP) | Deal Intelligence Workbook
B3: NYSE: SHOP | Public Equity Long | Entry: ~$108/share | PT: $150 | May 2026
B5: Workbook Navigation
B6: Tab | C6: Purpose | D6: Key Inputs
B7: INPUTS | C7: Deal assumptions, entry/exit, thesis, NTB names | D7: Shopify entry at $108/share; 3-yr hold to FY2028
B8: FINANCIALS | C8: Historical P&L — FY2022–FY2025A (adj. non-GAAP) | D8: Pre-populated; edit to override
B9: FINANCIAL MODEL | C9: Operating model — FY2022A + FY2026–2030E projections | D9: Yellow projection assumption cells
B10: DRIVER TREE | C10: Thesis decomposition — GMV, Payments, AI, Enterprise | D10: Base/Upside EV per driver; NTB linkage
B11: NTB REGISTRY | C11: 6 Shopify NTBs — evidence, MOIC impact, gaps | D11: Evidence status; MOIC impact ($M)
B12: KPI TREE | C12: Shopify KPI hierarchy mapped to financial model | D12: Budget (consensus) vs. actual (Q1'26A)
B13: MOIC BRIDGE | C13: MOIC waterfall — entry equity to exit by NTB | D13: Pulls from NTB Registry & INPUTS
B15: Investment Summary
B16: Metric | C16: Value | D16: Source
B17: Share Price (Entry) | C17: $108 | D17: Post-Q1'26 earnings — May 6, 2026
B18: Enterprise Value | C18: ~$135B | D18: Mkt cap ~$141B less net cash ~$6.3B (FY25 + Q1 FCF)
B19: Q1'26 Revenue | C19: $3,170M | D19: Shopify Q1'26 earnings release
B20: Q1'26 GMV | C20: $100.7B | D20: +35% YoY; first $100B+ quarter
B21: Q1'26 FCF Margin | C21: 15.0% | D21: $476M FCF on $3,170M revenue
B22: FY2026E Revenue | C22: $14,818M | D22: Model FY2026E consensus; GS/JPM/Baird buildup
B23: FY2026E EBITDA Mgn | C23: ~18.8% | D23: Model: ~$2,790M EBITDA on $14,818M revenue
B24: 12-mo Price Target | C24: $150 | D24: +39% upside; memo thesis
B25: 3-yr Base MOIC | C25: ~1.58x | D25: 45x FY2028E EBITDA $4.7B + $12.4B net cash (model)
B26: Conviction Level | C26: HIGH | D26: See NTB Registry for gating items
B28: Color Coding
B29: Color | C29: Meaning | D29: Action
B30: BLUE text / YELLOW bg | C30: BLUE text / YELLOW bg | D30: Hardcoded input — override for scenario analysis
B31: BLACK text | C31: BLACK text | D31: Formula — do not overwrite
B32: GREEN text | C32: GREEN text | D32: Cross-sheet link — do not overwrite
B33: Green background | C33: Green background | D33: Confirmed / PASS evidence status
B34: Orange background | C34: Orange background | D34: Partial — needs more evidence
B35: Red background | C35: Red background | D35: Gap / CRITICAL — NTB not yet supported

Sheet INPUTS
B2: Deal Inputs — Shopify, Inc. (SHOP)
B4: Company & Deal
B5: Field | C5: Value
B6: Company Name | C6: Shopify, Inc. (SHOP)
B7: Deal Type | C7: Public Equity Long
B8: Sector | C8: Technology / eCommerce Infrastructure
B9: Investment Thesis (one sentence) | C9: Dominant commerce OS processing $100B+ qtrly GMV; Payments take-rate compounding 40%+ YoY; AI-native architecture positions SHOP as agentic-commerce infrastructure layer; post-Q1 selloff creates entry at 9.1x FY26E EV/Revenue.
B10: Entry Year | C10: 2026
B11: Exit Year (projected) | C11: 2028
B13: Entry Assumptions (at $108/share — May 2026)
B14: Metric ($M unless noted) | C14: Value
B15: Entry Revenue ($M) [FY2026E, model] | C15: 14818
B16: Entry EBITDA ($M) [FY2026E, 18.8% adj.] | C16: 2790
B17: Entry EBITDA Margin | C17: 0.188
B18: Entry EV/EBITDA Multiple [NTM FY2026E] | C18: 48.5
B19: Entry EV ($M) [=EBITDA × Multiple] | C19: =C16*C18 -> 135315
B20: Net Debt at Entry ($M) [net cash: FY25 + Q1'26 FCF] | C20: -6254
B21: Equity Invested ($M) [=EV − Net Debt] | C21: =C19-C20 -> 141569
B23: Exit Assumptions (FY2028E Base Case)
B24: Metric | C24: Value
B25: Exit Revenue ($M) [FY2028E, model] | C25: 22138
B26: Exit EBITDA ($M) [FY2028E, ~21.2% margin] | C26: 4687
B27: Exit EV/EBITDA Multiple | C27: 45
B28: Exit EV ($M) [=EBITDA × Multiple] | C28: =C26*C27 -> 210915
B29: Net Debt at Exit ($M) [model cash $12.4B, $0 debt] | C29: -12369
B30: Proceeds to Equity ($M) [=Exit EV − Net Debt] | C30: =C28-C29 -> 223284
B32: Returns Summary
B33: Metric | C33: Value
B34: Gross MOIC | C34: =IFERROR(C30/C21,"-") -> 1.5772097
B35: Holding Period (Years) | C35: =IFERROR(C11-C10,"-") -> 2
B36: Implied IRR (approx) | C36: =IFERROR(POWER(C30/C21,1/(C11-C10))-1,"-") -> 0.2558701
B38: NTB Registry — Need-to-Believe Statements
B39: Shopify has 6 NTBs. Statements below link to NTB Registry & Driver Tree tabs.
B40: NTB # | C40: NTB Statement
B41: NTB 1 | C41: NTB-1: GMV growth sustains 25%+ through FY2027 despite tougher comps & FX normalisation [H / LOW / CRITICAL]
B42: NTB 2 | C42: NTB-2: Shopify Payments GPV penetration reaches 70%+ within 24 months; take-rate expands to 2.50%+ of GMV [H / MEDIUM / CRITICAL]
B43: NTB 3 | C43: NTB-3: AI-driven commerce (Sidekick, UCP, agentic checkout) is net revenue-positive; LLM cost inflation contained [H / LOW / CRITICAL]
B44: NTB 4 | C44: NTB-4: Enterprise wins (Shopify Plus) are durable and do not erode margins via bespoke development [E / MEDIUM / NON-CRITICAL]
B45: NTB 5 | C45: NTB-5: FCF margin expands from 15-17% to 20%+ by FY2028 without sacrificing 25%+ revenue growth [E / MEDIUM / PARTIAL]
B46: DRIVER TREE ASSUMPTIONS
...

Sheet FINANCIALS
B2: Historical Financials — Shopify FY2022–FY2025A (Adj. Non-GAAP, $M)
B4: Adj. non-GAAP figures. Revenue/GP/EBITDA from earnings releases. OpEx split approximate. Sources: Shopify Q1'26 earnings; GS, JPM, Citizens, Baird, KeyBanc research (May 2026).
B6: Line Item ($M) | C6: FY2022 | D6: FY2023 | E6: FY2024 | F6: FY2025A | G6: Notes / Source
B7: INCOME STATEMENT
B8: Revenue ($M) | C8: 5600 | D8: 7060 | E8: 8880 | F8: 11556 | G8: Shopify Q1/Q4'26 earnings releases; FY2025A +30.2% YoY
B9: YoY Growth % | D9: 0.262 | E9: 0.258 | F9: 0.302 | G9: Calculated YoY
B10: Cost of Revenue ($M) | C10: 2862 | D10: 3604 | E10: 4504 | F10: 5800 | G10: Blended: Sub ~20% COGS, MS ~62% COGS
B11: Gross Profit ($M) | C11: 2733 | D11: 3457 | E11: 4380 | F11: 5756 | G11: Blended GM: 48.8% (FY22) → 49.8% (FY25)
B12: Gross Margin % | C12: 0.488 | D12: 0.49 | E12: 0.493 | F12: 0.498
B13: Sales & Marketing ($M) | C13: 895 | D13: 888 | E13: 1043 | F13: 1422 | G13: Non-GAAP (excl. SBC)
B14: Research & Development ($M) | C14: 810 | D14: 729 | E14: 1155 | F14: 1244 | G14: Reduced post-2022 workforce restructuring
B15: General & Administrative ($M) | C15: 806 | D15: 840 | E15: 599 | F15: 1080 | G15: Non-GAAP
B16: Total Operating Expenses ($M) | C16: 2511 | D16: 2457 | E16: 2797 | F16: 3746 | G16: Sum S&M + R&D + G&A (non-GAAP)
B17: EBITDA (adj.) ($M) | C17: 44 | D17: 813 | E17: 1509 | F17: 1996 | G17: Non-GAAP adj. EBITDA; source: earnings releases + GS/JPM
B18: EBITDA Margin % | C18: 0.008 | D18: 0.115 | E18: 0.17 | F18: 0.173
B19: D&A ($M) | C19: 200 | D19: 235 | E19: 265 | F19: 310 | G19: Approximate; ~3.6% → 2.7% of revenue
B20: EBIT ($M) | C20: 22 | D20: 765 | E20: 1318 | F20: 1700 | G20: EBITDA minus D&A
B21: Interest Income/(Expense) ($M) | C21: -85 | D21: -195 | E21: -232 | F21: -295 | G21: Net interest income (Shopify has net cash position)
B22: EBT ($M) | C22: 107 | D22: 960 | E22: 1550 | F22: 1995
B23: Tax ($M) | C23: 16 | D23: 144 | E23: 233 | F23: 299 | G23: Effective rate ~15% on adj. basis
B24: Net Income (adj.) ($M) | C24: 91 | D24: 816 | E24: 1317 | F24: 1696 | G24: Adj. net income (non-GAAP)
B26: BALANCE SHEET (KEY ITEMS)
B27: Cash & Equivalents ($M) | C27: 5053 | D27: 5008 | E27: 5479 | F27: 5778 | G27: Q4 balance; FY2025 cash per Q1'26 BS
B28: Total Debt ($M) | C28: 913 | D28: 916 | E28: 0 | F28: 0 | G28: $913M conv. notes repaid FY2024; $0 thereafter
B29: Net Debt ($M) [neg = net cash] | C29: -4140 | D29: -4092 | E29: -5479 | F29: -5778 | G29: Negative = net cash
B30: Total Assets ($M) | C30: 9500 | D30: 10900 | E30: 12800 | F30: 16200 | G30: Total assets per annual 10-K
B32: CASH FLOW (KEY ITEMS)
B33: Operating Cash Flow ($M) | C33: -136 | D33: 944 | E33: 1616 | F33: 2033 | G33: OCF = FCF + Capex
B34: Capex ($M) | C34: 50 | D34: 39 | E34: 19 | F34: 26 | G34: ~1.8% of revenue; primarily technology infrastructure
B35: Free Cash Flow ($M) | C35: -186 | D35: 905 | E35: 1597 | F35: 2007 | G35: FCF = OCF - Capex; FY2022: -$186M (growth investment); FY2025A $2,007M (17.4%)

Sheet FINANCIAL MODEL
B2: Financial Model — Shopify Historical & Projections
B4: Line Item ($M) | C4: FY2022 | D4: FY2023 | E4: FY2024 | F4: FY2025A | G4: FY2026E | H4: FY2027E | I4: FY2028E | J4: FY2029E | K4: FY2030E | L4: Notes
B5: Projection Assumptions (Yellow = change for scenario analysis)
B6: FY2026E–FY2030E assumptions driven by consensus estimates + IC memo thesis.
B7: Revenue Growth % | G7: 0.282 | H7: 0.232 | I7: 0.212 | J7: 0.2 | K7: FY2026E: +28.2% (model); decel to +18% by FY2030E | L7: FY2026E: +29% (consensus); decel to +18% by FY2030E
B8: Gross Margin % | G8: 0.5 | H8: 0.505 | I8: 0.51 | J8: 0.515 | K8: 0.52 | L8: 50.0%–52.0%; modest Sub mix uplift
B9: S&M % of Revenue | G9: 0.125 | H9: 0.12 | I9: 0.118 | J9: 0.115 | K9: 0.112 | L9: 12.5% → 11.2%; OpEx leverage on scale
B10: R&D % of Revenue | G10: 0.113 | H10: 0.115 | I10: 0.115 | J10: 0.113 | K10: 0.11 | L10: 11.3% → 11.0%; AI capex partially capitalised
B11: G&A % of Revenue | G11: 0.075 | H11: 0.076 | I11: 0.077 | J11: 0.075 | K11: 0.073 | L11: 7.5% → 7.3%; fixed overhead scale benefit
B12: D&A % of Revenue | G12: 0.028 | H12: 0.027 | I12: 0.026 | J12: 0.025 | K12: 0.024 | L12: 2.8% → 2.4%; intangible amortisation declining
B13: Tax Rate % | G13: 0.15 | H13: 0.15 | I13: 0.15 | J13: 0.15 | K13: 0.15 | L13: 15% effective; SBC deductions + R&D credits
B14: Capex % of Revenue | G14: 0.017 | H14: 0.016 | I14: 0.015 | J14: 0.015 | K14: 0.014 | L14: 1.7% → 1.4%; lean capex model
B16: Income Statement
B17: Revenue | C17: 5595 | D17: 7061 | E17: 8884 | F17: 11556 | G17: =F17*(1+G7) -> 14814.792 | H17: =G17*(1+H7) -> 18251.824 | I17: =H17*(1+I7) -> 22121.21 | J17: =I17*(1+J7) -> 26545.452 | K17: =J17*(1+K7) -> #VALUE! | L17: Q1'26A $3,170M (+34% YoY); FY2026E consensus $14,885M (+29%)
B18: YoY Growth % | D18: 0.262 | E18: 0.258 | F18: 0.302 | G18: =IFERROR(G17/F17-1,"-") -> 0.282 | H18: =IFERROR(H17/G17-1,"-") -> 0.232 | I18: =IFERROR(I17/H17-1,"-") -> 0.212 | J18: =IFERROR(J17/I17-1,"-") -> 0.2 | K18: =IFERROR(K17/J17-1,"-") -> -
B19: Gross Profit | C19: 2733 | D19: 3457 | E19: 4380 | F19: 5756 | G19: =G17*G8 -> 7407.396 | H19: =H17*H8 -> 9217.171 | I19: =I17*I8 -> 11281.817 | J19: =J17*J8 -> 13670.908 | K19: =K17*K8 -> #VALUE! | L19: Sub Solutions ~80% GM; Merchant Solutions ~38% GM; blended expands
B20: Gross Margin % | C20: 0.488 | D20: 0.49 | E20: 0.493 | F20: 0.498 | G20: =IFERROR(G19/G17,"-") -> 0.5 | H20: =IFERROR(H19/H17,"-") -> 0.505 | I20: =IFERROR(I19/I17,"-") -> 0.51 | J20: =IFERROR(J19/J17,"-") -> 0.515 | K20: =IFERROR(K19/K17,"-") -> -
B21: Sales & Marketing | C21: 895 | D21: 888 | E21: 1043 | F21: 1422 | G21: =G17*G9 -> 1851.849 | H21: =H17*H9 -> 2190.2188 | I21: =I17*I9 -> 2610.3028 | J21: =J17*J9 -> 3052.727 | K21: =K17*K9 -> #VALUE!
B22: Research & Development | C22: 810 | D22: 729 | E22: 1155 | F22: 1244 | G22: =G17*G10 -> 1674.0715 | H22: =H17*H10 -> 2098.9597 | I22: =I17*I10 -> 2543.9392 | J22: =J17*J10 -> 2999.6361 | K22: =K17*K10 -> #VALUE! | L22: AI/Sidekick investment headwind ~FY2026–27
B23: General & Administrative | C23: 806 | D23: 840 | E23: 599 | F23: 1080 | G23: =G17*G11 -> 1111.1094 | H23: =H17*H11 -> 1387.1386 | I23: =I17*I11 -> 1703.3332 | J23: =J17*J11 -> 1990.9089 | K23: =K17*K11 -> #VALUE!
B24: Total OpEx | C24: 2511 | D24: 2457 | E24: 2797 | F24: 3746 | G24: =G21+G22+G23 -> 4637.0299 | H24: =H21+H22+H23 -> 5676.3172 | I24: =I21+I22+I23 -> 6857.5752 | J24: =J21+J22+J23 -> 8043.2721 | K24: =K21+K22+K23 -> #VALUE! | L24: Q1'26 OpEx/Rev = 32%; target 28% by FY2030E via operating leverage
B25: EBITDA (adj.) | C25: 44 | D25: 813 | E25: 1509 | F25: 1996 | G25: =G19-G24 -> 2770.3661 | H25: =H19-H24 -> 3540.8538 | I25: =I19-I24 -> 4424.2421 | J25: =J19-J24 -> 5627.6359 | K25: FY2025A 17.3% (model); FY2026E ~18.8%; FY2028E ~21.2% | L25: FY2025A 17.4%; FY2026E ~18.7% consensus; FY2028E base ~20%
B26: EBITDA Margin % | C26: 0.008 | D26: 0.115 | E26: 0.17 | F26: 0.173 | G26: =IFERROR(G25/G17,"-") -> 0.187 | H26: =IFERROR(H25/H17,"-") -> 0.194 | I26: =IFERROR(I25/I17,"-") -> 0.2 | J26: =IFERROR(J25/J17,"-") -> 0.212 | K26: =IFERROR(K25/K17,"-") -> -
B27: D&A | C27: 200 | D27: 235 | E27: 265 | F27: 310 | G27: =G17*G12 -> 414.81418 | H27: =H17*H12 -> 492.79924 | I27: =I17*I12 -> 575.15147 | J27: =J17*J12 -> 663.63631 | K27: =K17*K12 -> #VALUE!
B28: EBIT | C28: 22 | D28: 765 | E28: 1318 | F28: 1700 | G28: =G25-G27 -> 2355.5519 | H28: =H25-H27 -> 3048.0546 | I28: =I25-I27 -> 3849.0906 | J28: =J25-J27 -> 4963.9996 | K28: =K25-K27 -> #VALUE!
B29: Interest Income/(Expense) | C29: -85 | D29: -195 | E29: -232 | F29: -295 | L29: Shopify earns net interest on ~$6-9B cash; model as income (negative expense)
B30: EBT | C30: 107 | D30: 960 | E30: 1550 | F30: 1995 | G30: =G28-G29 -> 2355.5519 | H30: =H28-H29 -> 3048.0546 | I30: =I28-I29 -> 3849.0906 | J30: =J28-J29 -> 4963.9996 | K30: =K28-K29 -> #VALUE!
B31: Tax | C31: 16 | D31: 144 | E31: 233 | F31: 299 | G31: =G30*G13 -> 353.33279 | H31: =H30*H13 -> 457.20818 | I31: =I30*I13 -> 577.36359 | J31: =J30*J13 -> 744.59994 | K31: =K30*K13 -> #VALUE! | L31: ~15% effective adj. rate; SBC deductions support
B32: Net Income (adj.) | C32: 91 | D32: 816 | E32: 1317 | F32: 1696 | G32: =G30-G31 -> 2002.2191 | H32: =H30-H31 -> 2590.8464 | I32: =I30-I31 -> 3271.727 | J32: =J30-J31 -> 4219.3997 | K32: =K30-K31 -> #VALUE!
B34: Free Cash Flow
B35: EBITDA (adj.) | G35: =G25 -> 2770.3661 | H35: =H25 -> 3540.8538 | I35: =I25 -> 4424.2421 | J35: =J25 -> 5627.6359 | K35: =K25 -> FY2025A 17.3% (model); FY2026E ~18.8%; FY2028E ~21.2%
B36: Less: Capex | C36: 50 | D36: 39 | E36: 19 | F36: 26 | G36: =G17*G14 -> 251.85146 | H36: =H17*H14 -> 292.02918 | I36: =I17*I14 -> 331.81816 | J36: =J17*J14 -> 398.18179 | K36: =K17*K14 -> #VALUE! | L36: ~1.7%→1.4% of rev; technology infrastructure + office
B37: Less: Interest & Other | L37: Leave blank; interest income captured in NI above
B38: Free Cash Flow | C38: -186 | D38: 905 | E38: 1597 | F38: 2007 | G38: =G25-G36-G37 -> 2518.5146 | H38: =H25-H36-H37 -> 3248.8246 | I38: =I25-I36-I37 -> 4092.4239 | J38: =J25-J36-J37 -> 5229.4541 | K38: FY2022: -$186M; FY2025A $2,007M (17.4%); FY2028E $4,274M (19.3%) | L38: FY2025A $2,007M (17.4%); FY2026E ~$2,610M cons (17.5%); FY2028E ~$4.1B target
B40: Shopify-Specific KPIs (Supplemental)
B41: GMV ($B) | C41: 197.3 | D41: 235.9 | E41: 292.3 | F41: 378.4 | G41: 477.8 | H41: 583 | I41: 699.6 | J41: 871 | K41: Model FY2025A $378.4B (+29% YoY); FY2028E $699.6B (+20%) | L41: Q1'26A: $100.7B (+35%); FY2025A ~$329B (+23%)
B42: GPV Penetration % of GMV | C42: 0.561 | D42: 0.6 | E42: 0.643 | F42: 0.68 | G42: 0.71 | H42: 0.75 | I42: 0.79 | J42: 0.73 | K42: GPV% FY2025A: 68%; FY2026E: 71%; FY2028E: 79% (model) | L42: Q1'26A: 67%; targeting 72%+ by FY2028
B43: Merchant Solutions Rev/GMV (Take Rate) | C43: 0.0208 | D43: 0.0221 | E43: 0.0223 | F43: 0.0233 | G43: 0.0241 | H43: 0.025 | I43: 0.0259 | J43: 0.025 | K43: Attach rate FY2025A: 2.33%; FY2028E: 2.59% (model) | L43: Q1'26A: 2.40% (+7bps YoY)
B44: MRR ($M) | C44: 109.5 | D44: 144 | E44: 178 | F44: 205 | G44: 239 | H44: 267 | I44: 291 | J44: 340 | K44: MRR FY2025A: $205M; FY2026E: $239M; FY2028E: $291M (model) | L44: Q1'26A: $212M (+16% YoY); Plus ~28% of MRR

Sheet KPI TREE
B2: KPI Tree — Shopify Management Plan Audit
B4: FY2026E Budget = Street consensus (May 2026). Actual = Q1'26A annualised or FY2025A. Green = on track. Orange = watch. Red = behind plan.
G5: =+G11*12 -> 2460
B6: Lvl | C6: KPI Name | D6: Category | E6: Financial Model Line | F6: Frequency | G6: FY2025A Actual | H6: FY2026E Budget | I6: FY2028E Exit | J6: Δ vs Budget | K6: Status | L6: Notes
B7: NS | C7: NORTH STAR — GMV ($B) | D7: Scale | F7: Quarterly | G7: ='FINANCIAL MODEL'!F41 -> 378.4 | H7: ='FINANCIAL MODEL'!G41 -> 477.8 | I7: ='FINANCIAL MODEL'!I41 -> 699.6 | J7: =IFERROR((G7-H7)/ABS(H7),"-") -> -0.20803684 | K7: =IFERROR(IF((G7-H7)/ABS(H7)>-0.05,"On Track",IF((G7-H7)/ABS(H7)>-0.15,"Watch","Behind Plan")),"-") -> Behind Plan | L7: Q1'26A: $100.7B (+35%); FY2026E: $489B consensus
B8: 1 | C8: Total Revenue ($M) | D8: Growth | F8: Monthly | G8: ='FINANCIAL MODEL'!F17 -> 11556 | H8: ='FINANCIAL MODEL'!G17 -> 14814.792 | I8: ='FINANCIAL MODEL'!I17 -> 22121.21 | J8: =IFERROR((G8-H8)/ABS(H8),"-") -> -0.2199688 | K8: =IFERROR(IF((G8-H8)/ABS(H8)>-0.05,"On Track",IF((G8-H8)/ABS(H8)>-0.15,"Watch","Behind Plan")),"-") -> Behind Plan | L8: Q1'26A: $3,170M (+34%); consensus $14.9B
B9: 2 | C9: Subscription Solutions ($M) | D9: Growth | F9: Monthly | G9: ='FINANCIAL MODEL'!F17-'FINANCIAL MODEL'!F41*'FINANCIAL MODEL'!F43*1000 -> 2739.28 | H9: =INPUTS!C60 -> 3299.812 | I9: =INPUTS!$C$61 -> 4001.5704 | J9: =IFERROR((G9-H9)/ABS(H9),"-") -> -0.16986786 | K9: =IFERROR(IF((G9-H9)/ABS(H9)>-0.05,"On Track",IF((G9-H9)/ABS(H9)>-0.15,"Watch","Behind Plan")),"-") -> Behind Plan | L9: Q1'26A: $750M (+21%); 23% of Q1 rev
B10: 2 | C10: Merchant Solutions ($M) | D10: Growth | F10: Monthly | G10: ='FINANCIAL MODEL'!F41*'FINANCIAL MODEL'!F43*1000 -> 8816.72 | H10: =INPUTS!C56 -> 11514.98 | I10: =INPUTS!$C$57 -> 18119.64 | J10: =IFERROR((G10-H10)/ABS(H10),"-") -> -0.23432607 | K10: =IFERROR(IF((G10-H10)/ABS(H10)>-0.05,"On Track",IF((G10-H10)/ABS(H10)>-0.15,"Watch","Behind Plan")),"-") -> Behind Plan | L10: Q1'26A: $2,420M (+39%); 77% of Q1 rev
B11: 2 | C11: MRR ($M) | D11: Growth | F11: Monthly | G11: ='FINANCIAL MODEL'!F44 -> 205 | H11: ='FINANCIAL MODEL'!G44 -> 239 | I11: ='FINANCIAL MODEL'!I44 -> 291 | J11: =IFERROR((G11-H11)/ABS(H11),"-") -> -0.14225941 | K11: =IFERROR(IF((G11-H11)/ABS(H11)>-0.05,"On Track",IF((G11-H11)/ABS(H11)>-0.15,"Watch","Behind Plan")),"-") -> Watch | L11: Q1'26A: $212M (+16%); Plus ~28%
B12: 1 | C12: Blended Gross Margin | D12: Margin | F12: Monthly | G12: =IFERROR('FINANCIAL MODEL'!F19/'FINANCIAL MODEL'!F17,"-") -> 0.49809623 | H12: ='FINANCIAL MODEL'!G8 -> 0.5 | I12: =IFERROR('FINANCIAL MODEL'!I19/'FINANCIAL MODEL'!I17,"-") -> 0.51 | J12: =IFERROR((G12-H12)*100,"-") -> -0.19037729 | K12: =IFERROR(IF((G12-H12)/ABS(H12)>-0.05,"On Track",IF((G12-H12)/ABS(H12)>-0.15,"Watch","Behind Plan")),"-") -> On Track | L12: Q1'26A: 48.8%; modest improvement expected
B13: 2 | C13: Sub Solutions Gross Margin | D13: Margin | F13: Monthly | G13: 0.8 | H13: 0.8 | I13: 0.82 | J13: =IFERROR((G13-H13)*100,"-") -> 0 | K13: =IFERROR(IF((G13-H13)/ABS(H13)>-0.05,"On Track",IF((G13-H13)/ABS(H13)>-0.15,"Watch","Behind Plan")),"-") -> On Track | L13: AI/LLM cost headwind; -10bps YoY in Q1'26
B14: 2 | C14: Merchant Solutions Gross Margin | D14: Margin | F14: Monthly | G14: 0.375 | H14: 0.38 | I14: 0.4 | J14: =IFERROR((G14-H14)*100,"-") -> -0.5 | K14: =IFERROR(IF((G14-H14)/ABS(H14)>-0.05,"On Track",IF((G14-H14)/ABS(H14)>-0.15,"Watch","Behind Plan")),"-") -> On Track | L14: Payments mix increasing; take rate expanding
B15: 1 | C15: Adj. EBITDA Margin | D15: Margin | F15: Monthly | G15: ='FINANCIAL MODEL'!F26 -> 0.173 | H15: ='FINANCIAL MODEL'!G26 -> 0.187 | I15: ='FINANCIAL MODEL'!I26 -> 0.2 | J15: =IFERROR((G15-H15)*100,"-") -> -1.4 | K15: =IFERROR(IF((G15-H15)/ABS(H15)>-0.05,"On Track",IF((G15-H15)/ABS(H15)>-0.15,"Watch","Behind Plan")),"-") -> Watch | L15: Q1'26A: 16.5% (adj.); opex leverage continues
B16: 2 | C16: S&M % of Revenue | D16: Efficiency | F16: Monthly | G16: 0.123 | H16: ='FINANCIAL MODEL'!G9 -> 0.125 | I16: ='FINANCIAL MODEL'!I9 -> 0.118 | J16: =IFERROR((G16-H16)*100,"-") -> -0.2 | K16: =IFERROR(IF((G16-H16)/ABS(H16)<0.05,"On Track",IF((G16-H16)/ABS(H16)<0.15,"Watch","Off Plan")),"-") -> On Track | L16: Q1'26A: ~12.1%
B17: 2 | C17: R&D % of Revenue | D17: Efficiency | F17: Monthly | G17: 0.108 | H17: ='FINANCIAL MODEL'!G10 -> 0.113 | I17: ='FINANCIAL MODEL'!I10 -> 0.115 | J17: =IFERROR((G17-H17)*100,"-") -> -0.5 | K17: =IFERROR(IF((G17-H17)/ABS(H17)<0.05,"On Track",IF((G17-H17)/ABS(H17)<0.15,"Watch","Off Plan")),"-") -> On Track | L17: AI/Sidekick investment increasing R&D as % rev
B18: 2 | C18: OpEx Total % of Revenue | D18: Efficiency | F18: Monthly | G18: 0.324 | H18: =IFERROR('FINANCIAL MODEL'!G24/'FINANCIAL MODEL'!G17,"-") -> 0.313 | I18: =IFERROR('FINANCIAL MODEL'!I24/'FINANCIAL MODEL'!I17,"-") -> 0.31 | J18: =IFERROR((G18-H18)*100,"-") -> 1.1 | K18: =IFERROR(IF((G18-H18)/ABS(H18)<0.05,"On Track",IF((G18-H18)/ABS(H18)<0.15,"Watch","Off Plan")),"-") -> On Track | L18: Q1'26 = 32%; targeting 31% FY2026E
B19: 1 | C19: GMV Specific KPIs | D19: Growth | F19: Quarterly | K19: N/A
B20: 2 | C20: GPV Penetration % GMV | D20: Payments | F20: Quarterly | G20: ='FINANCIAL MODEL'!F42 -> 0.68 | H20: ='FINANCIAL MODEL'!G42 -> 0.71 | I20: ='FINANCIAL MODEL'!I42 -> 0.79 | J20: =IFERROR((G20-H20)*100,"-") -> -3 | K20: =IFERROR(IF((G20-H20)/ABS(H20)>-0.05,"On Track",IF((G20-H20)/ABS(H20)>-0.15,"Watch","Behind Plan")),"-") -> On Track | L20: Q1'26A: 67%; +200bps/yr trajectory
B21: 2 | C21: Payments Take Rate (GPV/Rev) | D21: Payments | F21: Quarterly | G21: ='FINANCIAL MODEL'!F43 -> 0.0233 | H21: ='FINANCIAL MODEL'!G43 -> 0.0241 | I21: ='FINANCIAL MODEL'!I43 -> 0.0259 | J21: =IFERROR((G21-H21)*100,"-") -> -0.08 | K21: =IFERROR(IF((G21-H21)/ABS(H21)>-0.05,"On Track",IF((G21-H21)/ABS(H21)>-0.15,"Watch","Behind Plan")),"-") -> On Track | L21: Q1'26A: 2.40% (+7bps YoY)
B22: 2 | C22: B2B GMV Growth % | D22: Growth | F22: Quarterly | H22: 0.6 | I22: 0.85 | L22: Q1'26A: +80% YoY; early-stage, pre-scale
B23: 2 | C23: International GMV Growth % | D23: Growth | F23: Quarterly | H23: 0.35 | I23: 0.5 | L23: Q1'26A: +45% YoY; Europe +48%
B24: 1 | C24: Free Cash Flow ($M) | D24: Cash | F24: Monthly | G24: ='FINANCIAL MODEL'!F38 -> 2007 | H24: ='FINANCIAL MODEL'!G38 -> 2518.5146 | I24: ='FINANCIAL MODEL'!I38 -> 4092.4239 | J24: =IFERROR((G24-H24)/ABS(H24),"-") -> -0.20310171 | K24: =IFERROR(IF((G24-H24)/ABS(H24)>-0.05,"On Track",IF((G24-H24)/ABS(H24)>-0.15,"Watch","Behind Plan")),"-") -> Behind Plan | L24: Q1'26A: $476M (15%); full-yr cons $2.6B (17.5%)
B25: 2 | C25: FCF Margin | D25: Cash | F25: Monthly | G25: =IFERROR('FINANCIAL MODEL'!F38/'FINANCIAL MODEL'!F17,"-") -> 0.17367601 | H25: =IFERROR('FINANCIAL MODEL'!G38/'FINANCIAL MODEL'!G17,"-") -> 0.17 | I25: =IFERROR('FINANCIAL MODEL'!I38/'FINANCIAL MODEL'!I17,"-") -> 0.185 | J25: =IFERROR((G25-H25)*100,"-") -> 0.36760125 | K25: =IFERROR(IF((G25-H25)/ABS(H25)>-0.05,"On Track",IF((G25-H25)/ABS(H25)>-0.15,"Watch","Behind Plan")),"-") -> On Track | L25: Q2'26 guide: mid-teens (MCA reclass headwind)
B26: 2 | C26: Capex % Revenue | D26: Cash | F26: Monthly | G26: 0.017 | H26: ='FINANCIAL MODEL'!G14 -> 0.017 | I26: ='FINANCIAL MODEL'!I14 -> 0.015 | J26: =IFERROR((G26-H26)*100,"-") -> 0 | K26: =IFERROR(IF((G26-H26)/ABS(H26)<0.05,"On Track",IF((G26-H26)/ABS(H26)<0.15,"Watch","Off Plan")),"-") -> On Track | L26: Lean capex model maintained

Sheet DRIVER TREE
B1: DRIVER TREE | SHOPIFY
B2: Paasche revenue decomposition: GMV Volume Effect + Attach Rate Improvement → EBITDA → EV → MOIC
B5: REVENUE DRIVER DECOMPOSITION — EBITDA — EV — MOIC
B6: Driver | C6: Source | D6: KPI Metric | E6: Unit | F6: FY2025A | G6: FY2026E (Entry) | H6: FY2028E (Exit) | I6: Δ (28E–26E) | J6: Revenue Impact ($M) | K6: Incr. EBITDA % | L6: EBITDA Impact ($M) | M6: EV Impact ($M, ×entry) | N6: MOIC Delta (×)
B7: MERCHANT SOLUTIONS REVENUE | C7: Model | D7: Revenue = GMV × Attach Rate | E7: $M | G7: =INPUTS!$C$56 -> 11514.98 | H7: =INPUTS!$C$57 -> 18119.64 | I7: =H7-G7 -> 6604.66
B8: GMV Volume Effect | D8: ΔGMV × entry attach rate (240.9 bps) — sub-driver splits per INPUTS rows 68–71
B9: Same-Cohort Productivity | C9: Analyst | D9: Same-cohort GMV (40% of ΔGMV) | E9: $B | F9: ='FINANCIAL MODEL'!F41*INPUTS!$C$68 -> 151.36 | G9: =INPUTS!$C$48*INPUTS!$C$68 -> 191.12 | H9: =INPUTS!$C$49*INPUTS!$C$68 -> 279.84 | I9: =H9-G9 -> 88.72 | J9: =I9*(INPUTS!$C$50/10000)*1000 -> 2138.152 | K9: =INPUTS!$C$75 -> 0.214 | L9: =J9*K9 -> 457.56453 | M9: =L9*INPUTS!$C$18 -> 22191.88 | N9: =M9/INPUTS!$C$21 -> 0.15675663
B10: New Merchant Acquisition | C10: Analyst | D10: New merchant GMV (30% of ΔGMV) | E10: $B | F10: ='FINANCIAL MODEL'!F41*INPUTS!$C$69 -> 113.52 | G10: =INPUTS!$C$48*INPUTS!$C$69 -> 143.34 | H10: =INPUTS!$C$49*INPUTS!$C$69 -> 209.88 | I10: =H10-G10 -> 66.54 | J10: =I10*(INPUTS!$C$50/10000)*1000 -> 1603.614 | K10: =INPUTS!$C$75 -> 0.214 | L10: =J10*K10 -> 343.1734 | M10: =L10*INPUTS!$C$18 -> 16643.91 | N10: =M10/INPUTS!$C$21 -> 0.11756747
B11: Geographic Expansion (International) | C11: IC Memo | D11: International GMV (20% of ΔGMV) — +45% YoY | E11: $B | F11: ='FINANCIAL MODEL'!F41*INPUTS!$C$70 -> 75.68 | G11: =INPUTS!$C$48*INPUTS!$C$70 -> 95.56 | H11: =INPUTS!$C$49*INPUTS!$C$70 -> 139.92 | I11: =H11-G11 -> 44.36 | J11: =I11*(INPUTS!$C$50/10000)*1000 -> 1069.076 | K11: =INPUTS!$C$75 -> 0.214 | L11: =J11*K11 -> 228.78226 | M11: =L11*INPUTS!$C$18 -> 11095.94 | N11: =M11/INPUTS!$C$21 -> 0.078378316
B12: B2B / POS / Channel | C12: IC Memo | D12: B2B / POS / Channel GMV (10% of ΔGMV) — +80% YoY | E12: $B | F12: ='FINANCIAL MODEL'!F41*INPUTS!$C$71 -> 37.84 | G12: =INPUTS!$C$48*INPUTS!$C$71 -> 47.78 | H12: =INPUTS!$C$49*INPUTS!$C$71 -> 69.96 | I12: =H12-G12 -> 22.18 | J12: =I12*(INPUTS!$C$50/10000)*1000 -> 534.538 | K12: =INPUTS!$C$75 -> 0.214 | L12: =J12*K12 -> 114.39113 | M12: =L12*INPUTS!$C$18 -> 5547.9699 | N12: =M12/INPUTS!$C$21 -> 0.039189158
B13: Subtotal: GMV Volume Effect | D13: Total ΔGMV × entry attach rate 240.9 bps | E13: $B | G13: =INPUTS!$C$48 -> 477.8 | H13: =INPUTS!$C$49 -> 699.6 | I13: =H13-G13 -> 221.8 | J13: =SUM(J9:J12) -> 5345.38 | K13: =INPUTS!$C$75 -> 0.214 | L13: =J13*K13 -> 1143.9113 | M13: =L13*INPUTS!$C$18 -> 55479.699 | N13: =M13/INPUTS!$C$21 -> 0.39189158
B14: Attach Rate Improvement | D14: Δattach rate × exit GMV — GPV + non-payments components
B15: GPV Penetration (71% → 79%) | C15: Model + IC Memo | D15: GPV% of GMV — IC Memo: $67M per 100bps at base GMV | E15: % | F15: ='FINANCIAL MODEL'!F42 -> 0.68 | G15: =INPUTS!$C$52 -> 0.71 | H15: =INPUTS!$C$53 -> 0.79 | I15: =(H15-G15)*100 -> 8 | J15: =(H15-G15)*100*INPUTS!$C$65*INPUTS!$C$49/INPUTS!$C$62 -> 990.97674 | K15: =INPUTS!$C$75 -> 0.214 | L15: =J15*K15 -> 212.06902 | M15: =L15*INPUTS!$C$18 -> 10285.348 | N15: =M15/INPUTS!$C$21 -> 0.072652541
B16: Non-Payments Attach (MCA, Balance, Markets) | C16: Model | D16: Residual attach rate (MCA, Balance, Markets) | E16: bps residual | J16: =J17-J15 -> 268.30326 | K16: =INPUTS!$C$75 -> 0.214 | L16: =J16*K16 -> 57.416897 | M16: =L16*INPUTS!$C$18 -> 2784.7195 | N16: =M16/INPUTS!$C$21 -> 0.019670404
B17: Subtotal: Attach Rate Improvement | D17: Total merch rev delta − GMV volume effect | E17: bps | G17: =INPUTS!$C$50 -> 241 | H17: =INPUTS!$C$51 -> 259 | I17: =H17-G17 -> 18 | J17: =INPUTS!$C$57-INPUTS!$C$56-J13 -> 1259.28 | K17: =INPUTS!$C$75 -> 0.214 | L17: =J17*K17 -> 269.48592 | M17: =L17*INPUTS!$C$18 -> 13070.067 | N17: =M17/INPUTS!$C$21 -> 0.092322946
B18: TOTAL: Merchant Solutions Revenue | C18: Model | E18: $M | G18: =INPUTS!$C$56 -> 11514.98 | H18: =INPUTS!$C$57 -> 18119.64 | I18: =H18-G18 -> 6604.66 | J18: =J13+J17 -> 6604.66 | K18: =L18 -> 1413.3972 | L18: =L13+L17 -> 1413.3972 | M18: =L18*INPUTS!$C$18 -> 68549.766 | N18: =M18/INPUTS!$C$21 -> 0.48421453
B20: SUBSCRIPTION SOLUTIONS REVENUE | C20: Model | D20: Revenue ≈ MRR × Revenue/MRR multiplier (INPUTS!C86) | E20: $M | G20: =INPUTS!$C$60 -> 3299.812 | H20: =INPUTS!$C$61 -> 4001.5704 | I20: =H20-G20 -> 701.75838
B21: MRR Build
B22: Plus / Enterprise MRR Growth | C22: Model | D22: Plus MRR ($M) — $25M+ GMV cohort, 28%→39% of MRR | E22: $M MRR | F22: =INPUTS!$C$80 -> 69.7 | G22: =INPUTS!$C$81 -> 83.6 | H22: =INPUTS!$C$82 -> 114.5 | I22: =H22-G22 -> 30.9 | J22: =I22*INPUTS!$C$86 -> 426.62841 | K22: =INPUTS!$C$76 -> 0.676 | L22: =J22*K22 -> 288.40081 | M22: =L22*INPUTS!$C$18 -> 13987.439 | N22: =M22/INPUTS!$C$21 -> 0.098802981
B23: Core SMB MRR Growth | C23: Model | D23: Core MRR ($M) — Basic/Standard/Advanced plans | E23: $M MRR | F23: =INPUTS!$C$83 -> 135.3 | G23: =INPUTS!$C$84 -> 155.6 | H23: =INPUTS!$C$85 -> 176.4 | I23: =H23-G23 -> 20.8 | J23: =I23*INPUTS!$C$86 -> 287.18029 | K23: =INPUTS!$C$76 -> 0.676 | L23: =J23*K23 -> 194.13388 | M23: =L23*INPUTS!$C$18 -> 9415.493 | N23: =M23/INPUTS!$C$21 -> 0.066508155
B24: TOTAL: Subscription Solutions Revenue | C24: Model | E24: $M | G24: =INPUTS!$C$60 -> 3299.812 | H24: =INPUTS!$C$61 -> 4001.5704 | I24: =H24-G24 -> 701.75838 | J24: =SUM(J22:J23) -> 713.8087 | K24: =SUM(L22:L23) -> 482.53468 | L24: =SUM(L22:L23) -> 482.53468 | M24: =L24*INPUTS!$C$18 -> 23402.932 | N24: =M24/INPUTS!$C$21 -> 0.16531114
B26: TOTAL REVENUE GROWTH | C26: Model | E26: $M | G26: =INPUTS!$C$58 -> 14814.792 | H26: =INPUTS!$C$59 -> 22121.21 | I26: =H26-G26 -> 7306.4184 | J26: =J18+J24 -> 7318.4687 | K26: =(L18+L24)/J26 -> 0.25906129 | L26: =L18+L24 -> 1895.9319 | M26: =M18+M24 -> 91952.698 | N26: =N18+N24 -> 0.64952566
B28: VALUE CREATION BRIDGE
B29: Component | J29: EBITDA Effect ($M) | K29: × Multiple | L29: EV Impact ($M) | N29: MOIC Delta (×)
B30: Revenue-Driven EBITDA Growth (EBITDA delta × entry multiple 48.5×) | J30: =L26 -> 1895.9319 | K30: =INPUTS!$C$18 -> 48.5 | L30: =J30*K30 -> 91952.698 | N30: =L30/INPUTS!$C$21 -> 0.64952566
B31: Multiple Compression (48.5× entry → 45.0× exit × exit EBITDA $4,687M) | J31: =(INPUTS!$C$27-INPUTS!$C$18)*INPUTS!$C$26 -> -16404.5 | K31: 1 | L31: =J31 -> -16404.5 | N31: =L31/INPUTS!$C$21 -> -0.11587636
B32: Net Cash Build (net cash $6.3B entry → $12.4B exit) | J32: =-(INPUTS!$C$29-INPUTS!$C$20) -> 6115 | K32: 1 | L32: =J32 -> 6115 | N32: =L32/INPUTS!$C$21 -> 0.043194485
B33: TOTAL VALUE CREATION | L33: =L30+L31+L32 -> 81663.198 | N33: =L33/INPUTS!$C$21 -> 0.57684379
B34: MOIC CHECK = 1.00× + attribution (should ≈ INPUTS!C34) | K34: INPUTS MOIC: | L34: =INPUTS!$C$34 -> 1.5772097 | N34: =1+N33 -> 1.5768438
B35: Paasche: EV = EBITDA delta × entry multiple 48.5×. Multiple compression uses exit EBITDA. Net cash sign: negative = cash-rich.

Sheet MOIC BRIDGE
B2: MOIC Bridge — Shopify Entry to Exit (FY2028E Base)
B4: Equity value waterfall from entry ($108/share) to exit (FY2028E base). NTB contributions pull from NTB Registry (incremental EV if NTB confirmed). Note: Shopify is a public equity long; MOIC reflects total return, not PE carry.
B6: Component | C6: Equity Value ($M) | D6: MOIC Contribution | E6: Cumulative MOIC
B7: Entry Equity Invested ($108/share × 1,307M) | C7: =INPUTS!C21 -> 141569 | D7: 1 | E7: =IFERROR(INPUTS!C21/INPUTS!C21,"-") -> 1
B8: NTB-1: GMV Sustains 25%+ Through FY2027 | C8: =IFERROR('NTB REGISTRY'!E7,"-") -> 67679.912 | D8: =IFERROR('NTB REGISTRY'!F7,"-") -> 0.47807014 | E8: =IFERROR(E7+D8,"-") -> 1.4780701
B9: NTB-2: Payments GPV Penetration to 70%+ | C9: =IFERROR('NTB REGISTRY'!E8,"-") -> 10285.348 | D9: =IFERROR('NTB REGISTRY'!F8,"-") -> 0.072652541 | E9: =IFERROR(E8+D9,"-") -> 1.5507227
B10: NTB-3: AI Commerce Net Revenue-Positive | C10: =IFERROR('NTB REGISTRY'!E9,"-") -> 0 | D10: =IFERROR('NTB REGISTRY'!F9,"-") -> 0 | E10: =IFERROR(E9+D10,"-") -> 1.5507227
B11: NTB-4: Enterprise Plus Margin Durable | C11: =IFERROR('NTB REGISTRY'!E10,"-") -> 13987.439 | D11: =IFERROR('NTB REGISTRY'!F10,"-") -> 0.098802981 | E11: =IFERROR(E10+D11,"-") -> 1.6495257
B12: NTB-5: FCF Margin Expands to 20%+ [not modeled in base case] | C12: 0 | D12: 0 | E12: =IFERROR(E11+D12,"-") -> 1.6495257
B13: NTB-6: Macro Does Not Materially Deteriorate [not modeled in base case] | C13: 0 | D13: 0 | E13: =IFERROR(E12+D13,"-") -> 1.6495257
B14: Multiple Re-rating / Compression (48.5x entry to 45.0x exit x $4.7B exit EBITDA) | C14: ='DRIVER TREE'!L31 -> -16404.5 | D14: ='DRIVER TREE'!N31 -> -0.11587636 | E14: =IFERROR(E13+D14,"-") -> 1.5336493
B15: Net Cash Build (Net cash $6.3B to $12.4B; INPUTS rows 20 / 29) | C15: ='DRIVER TREE'!L32 -> 6115 | D15: ='DRIVER TREE'!N32 -> 0.043194485 | E15: =IFERROR(E14+D15,"-") -> 1.5768438
B16: Exit Proceeds to Equity (FY2028E Base: 45x × $4.49B EBITDA + $8.5B net cash) | C16: =INPUTS!C30 -> 223284 | D16: =IFERROR(INPUTS!C30/INPUTS!C21,"-") -> 1.5772097 | E16: =IFERROR(INPUTS!C30/INPUTS!C21,"-") -> 1.5772097

Sheet NTB REGISTRY
B1: NTB REGISTRY · SHOPIFY DEAL WORKBOOK
B2: Investment thesis mapped to revenue drivers → EBITDA → EV → MOIC attribution. Base = model FY2028E. Upside = IC Memo bull case.
B3: Source: IC Memo v2 Pillars 1-4 mapped to DRIVER TREE. Base EV uses Paasche decomposition (×48.5 entry multiple). Upside = analyst thesis above model.
B5: NTB REGISTRY — THESIS TO VALUE ATTRIBUTION
B6: NTB | C6: Theme | D6: Thesis Summary (Key Assumption vs. Consensus) | E6: Base EV Impact ($M) | F6: Base MOIC Delta (×) | G6: Upside EV ($M) | H6: Upside MOIC (×) | I6: IC Memo Pillar | J6: Driver Tree Rows | K6: Rating / Status
B7: NTB 1 | C7: GMV Flywheel | D7: Thesis: Multiple independent GMV growth vectors (same-cohort expansion, new merchant acquisition, geographic expansion to 15 intl markets, B2B +80% YoY) sustain 20-22% GMV CAGR through FY2028E vs. consensus expectation of GMV deceleration driven by FX and tougher comps. Key: geographic and B2B channels reduce single-point-of-failure risk. [IC Memo: Pillar 1 — LOW evidence strength, THESIS-CRITICAL] | E7: ='DRIVER TREE'!M13+'DRIVER TREE'!M16+'DRIVER TREE'!M23 -> 67679.912 | F7: =IFERROR(E7/INPUTS!$C$21,"-") -> 0.47807014 | G7: 72056.306 | H7: 0.509 | I7: Pillar 1 | J7: Same-Cohort, New Merchant, Geographic, B2B/Channel | K7: OPEN — thesis-critical
B8: NTB 2 | C8: Payments Monetization | D8: Thesis: GPV penetration grows 71% → 79% FY2026-28E driven by Shop Pay expansion on non-Shopify storefronts, checkout optimization, and merchant incentives. Each 100bps penetration = $124M incremental revenue at exit GMV ($699.6B). Model assumes 8pp penetration gain; consensus (sell-side avg) ~74% FY2028E implies 5pp below model — model is already thesis-aligned. Non-payments (MCA, Balance) add $268M incremental. [IC Memo: Pillar 2 — HIGH evidence strength, Payments thesis CONFIRMED] | E8: ='DRIVER TREE'!M15 -> 10285.348 | F8: =IFERROR(E8/INPUTS!$C$21,"-") -> 0.072652541 | G8: 18294.277 | H8: 0.129 | I8: Pillar 2 | J8: GPV Penetration, Non-Payments Attach | K8: CONFIRMED — HIGH evidence
B9: NTB 3 | C9: AI Commerce Platform (Optionality) | D9: Thesis: Shopify's 20+ year proprietary commerce data creates a structural moat vs. general-purpose AI (2× conversion rate on AI-assisted orders vs. organic search Q1'26). AI revenue streams (Sidekick subscription, Usage-based Commerce Protocols) not yet in base model — pure optionality upside. No FY2028E base case contribution modeled. Upside scenario: $40B EV ($15B Sidekick + $25B UCP). [IC Memo: Pillar 3 — MEDIUM evidence strength, THESIS-CRITICAL for long-term] | E9: 0 | F9: 0 | G9: 40000 | H9: 0.283 | I9: Pillar 3 | J9: AI Sidekick (C1), AI UCP (C3) — upside only | K9: OPEN — hypothesis, not in model
B10: NTB 4 | C10: Enterprise Upmarket | D10: Thesis: $25M+ GMV cohort is fastest-growing segment Q1'26 with no SMB cannibalization. Plus MRR grows from $83.6M (FY2026E, 35% of MRR) to $114.5M (FY2028E, 39% of MRR) driving $427M incremental subscription revenue at ~82% gross margin. High-margin subscription mix shift benefits blended margins. Upside: Plus penetration accelerates to 45% of MRR ($137M) by FY2028E. [IC Memo: Pillar 4 — MEDIUM evidence strength, VALUATION OPTIONALITY] | E10: ='DRIVER TREE'!M22 -> 13987.439 | F10: =IFERROR(E10/INPUTS!$C$21,"-") -> 0.098802981 | G10: 31617.684 | H10: 0.223 | I10: Pillar 4 | J10: Plus/Enterprise MRR, Core SMB MRR | K10: WATCH — valuation optionality
B11: NTB 5 | C11: Multiple Compression (Risk) | D11: Risk: Entry at 48.5× EV/EBITDA creates structural headwind. Exit at 45× already assumes compression. Each 1× turn of additional compression = $4,687M additional EV reduction = -0.033x MOIC drag. Downside scenario: exit at 40× → additional -$23.4B EV → MOIC = 1.41× (vs. 1.58× base). Offsetting factor: EBITDA growth nearly triples ($2.79B → $4.69B), supporting multiple. [Macro risk: consumer softness, tariff impact on SMB GMV] | E11: ='DRIVER TREE'!L31 -> -16404.5 | F11: =IFERROR(E11/INPUTS!$C$21,"-") -> -0.11587636 | G11: -8202.25 | H11: -0.058 | I11: Macro / Risk | J11: Multiple Compression, Macro Consumer Risk | K11: STRUCTURAL — mitigant: EBITDA growth
B12: TOTAL | C12: Base + Multiple Compression + Net Cash | E12: =SUM(E7:E11)+'DRIVER TREE'!L32 -> 81663.198 | F12: =IFERROR(E12/INPUTS!$C$21,"-") -> 0.57684379
B13: MOIC CHECK | F13: =IFERROR(1+F12,"-") -> 1.5768438
