Workbook

Sheet COVER
B2: Shopify, Inc. (SHOP) | Deal Intelligence Workbook
B3: NYSE: SHOP | Public Equity Long | Entry: ~$108/share | PT: $150 | May 2026
B5: Workbook Navigation
B6: Tab | C6: Purpose | D6: Key Inputs
B7: INPUTS | C7: Deal assumptions, entry/exit, thesis, NTB names | D7: Shopify entry at $108/share; 3-yr hold to FY2028
B8: FINANCIALS | C8: Historical P&L — FY2022–FY2025A (adj. non-GAAP) | D8: Pre-populated; edit to override
B9: FINANCIAL MODEL | C9: Operating model — FY2022A + FY2026–2030E projections | D9: Yellow projection assumption cells
B10: DRIVER TREE | C10: Thesis decomposition — GMV, Payments, AI, Enterprise | D10: Base/Upside EV per driver; NTB linkage
B11: NTB REGISTRY | C11: 6 Shopify NTBs — evidence, MOIC impact, gaps | D11: Evidence status; MOIC impact ($M)
B12: KPI TREE | C12: Shopify KPI hierarchy mapped to financial model | D12: Budget (consensus) vs. actual (Q1'26A)
B13: MOIC BRIDGE | C13: MOIC waterfall — entry equity to exit by NTB | D13: Pulls from NTB Registry & INPUTS
B15: Investment Summary
B16: Metric | C16: Value | D16: Source
B17: Share Price (Entry) | C17: $108 | D17: Post-Q1'26 earnings — May 6, 2026
B18: Enterprise Value | C18: ~$135B | D18: Mkt cap ~$141B less net cash ~$6.3B (FY25 + Q1 FCF)
B19: Q1'26 Revenue | C19: $3,170M | D19: Shopify Q1'26 earnings release
B20: Q1'26 GMV | C20: $100.7B | D20: +35% YoY; first $100B+ quarter
B21: Q1'26 FCF Margin | C21: 15.0% | D21: $476M FCF on $3,170M revenue
B22: FY2026E Revenue | C22: $14,818M | D22: Model FY2026E consensus; GS/JPM/Baird buildup
B23: FY2026E EBITDA Mgn | C23: ~18.8% | D23: Model: ~$2,790M EBITDA on $14,818M revenue
B24: 12-mo Price Target | C24: $150 | D24: +39% upside; memo thesis
B25: 3-yr Base MOIC | C25: ~1.58x | D25: 45x FY2028E EBITDA $4.7B + $12.4B net cash (model)
B26: Conviction Level | C26: HIGH | D26: See NTB Registry for gating items
B28: Color Coding
B29: Color | C29: Meaning | D29: Action
B30: BLUE text / YELLOW bg | C30: BLUE text / YELLOW bg | D30: Hardcoded input — override for scenario analysis
B31: BLACK text | C31: BLACK text | D31: Formula — do not overwrite
B32: GREEN text | C32: GREEN text | D32: Cross-sheet link — do not overwrite
B33: Green background | C33: Green background | D33: Confirmed / PASS evidence status
B34: Orange background | C34: Orange background | D34: Partial — needs more evidence
B35: Red background | C35: Red background | D35: Gap / CRITICAL — NTB not yet supported

Sheet INPUTS
B2: Deal Inputs — Shopify, Inc. (SHOP)
B4: Company & Deal
B5: Field | C5: Value
B6: Company Name | C6: Shopify, Inc. (SHOP)
B7: Deal Type | C7: Public Equity Long
B8: Sector | C8: Technology / eCommerce Infrastructure
B9: Investment Thesis (one sentence) | C9: Dominant commerce OS processing $100B+ qtrly GMV; Payments take-rate compounding 40%+ YoY; AI-native architecture positions SHOP as agentic-commerce infrastructure layer; post-Q1 selloff creates entry at 9.1x FY26E EV/Revenue.
B10: Entry Year | C10: 2026
B11: Exit Year (projected) | C11: 2028
B13: Entry Assumptions (at $108/share — May 2026)
B14: Metric ($M unless noted) | C14: Value
B15: Entry Revenue ($M) [FY2026E, model] | C15: 14818
B16: Entry EBITDA ($M) [FY2026E, 18.8% adj.] | C16: 2790
B17: Entry EBITDA Margin | C17: 0.188
B18: Entry EV/EBITDA Multiple [NTM FY2026E] | C18: 48.5
B19: Entry EV ($M) [=EBITDA × Multiple] | C19: =C16*C18
B20: Net Debt at Entry ($M) [net cash: FY25 + Q1'26 FCF] | C20: -6254
B21: Equity Invested ($M) [=EV − Net Debt] | C21: =C19-C20
B23: Exit Assumptions (FY2028E Base Case)
B24: Metric | C24: Value
B25: Exit Revenue ($M) [FY2028E, model] | C25: 22138
B26: Exit EBITDA ($M) [FY2028E, ~21.2% margin] | C26: 4687
B27: Exit EV/EBITDA Multiple | C27: 45
B28: Exit EV ($M) [=EBITDA × Multiple] | C28: =C26*C27
B29: Net Debt at Exit ($M) [model cash $12.4B, $0 debt] | C29: -12369
B30: Proceeds to Equity ($M) [=Exit EV − Net Debt] | C30: =C28-C29
B32: Returns Summary
B33: Metric | C33: Value
B34: Gross MOIC | C34: =IFERROR(C30/C21,"-")
B35: Holding Period (Years) | C35: =IFERROR(C11-C10,"-")
B36: Implied IRR (approx) | C36: =IFERROR(POWER(C30/C21,1/(C11-C10))-1,"-")
B38: NTB Registry — Need-to-Believe Statements
B39: Shopify has 6 NTBs. Statements below link to NTB Registry & Driver Tree tabs.
B40: NTB # | C40: NTB Statement
B41: NTB 1 | C41: NTB-1: GMV growth sustains 25%+ through FY2027 despite tougher comps & FX normalisation [H / LOW / CRITICAL]
B42: NTB 2 | C42: NTB-2: Shopify Payments GPV penetration reaches 70%+ within 24 months; take-rate expands to 2.50%+ of GMV [H / MEDIUM / CRITICAL]
B43: NTB 3 | C43: NTB-3: AI-driven commerce (Sidekick, UCP, agentic checkout) is net revenue-positive; LLM cost inflation contained [H / LOW / CRITICAL]
B44: NTB 4 | C44: NTB-4: Enterprise wins (Shopify Plus) are durable and do not erode margins via bespoke development [E / MEDIUM / NON-CRITICAL]
B45: NTB 5 | C45: NTB-5: FCF margin expands from 15-17% to 20%+ by FY2028 without sacrificing 25%+ revenue growth [E / MEDIUM / PARTIAL]
B46: NTB 6 | C46: NTB-6: Consumer/macro does not materially deteriorate in FY2026-27, sustaining SMB GMV compounding [H / LOW / CRITICAL]
...

Sheet FINANCIALS
B2: Historical Financials — Shopify FY2022–FY2025A (Adj. Non-GAAP, $M)
B4: Adj. non-GAAP figures. Revenue/GP/EBITDA from earnings releases. OpEx split approximate. Sources: Shopify Q1'26 earnings; GS, JPM, Citizens, Baird, KeyBanc research (May 2026).
B6: Line Item ($M) | C6: FY2022 | D6: FY2023 | E6: FY2024 | F6: FY2025A | G6: Notes / Source
B7: INCOME STATEMENT
B8: Revenue ($M) | C8: 5600 | D8: 7060 | E8: 8880 | F8: 11556 | G8: Shopify Q1/Q4'26 earnings releases; FY2025A +30.2% YoY
B9: YoY Growth % | D9: 0.262 | E9: 0.258 | F9: 0.302 | G9: Calculated YoY
B10: Cost of Revenue ($M) | C10: 2862 | D10: 3604 | E10: 4504 | F10: 5800 | G10: Blended: Sub ~20% COGS, MS ~62% COGS
B11: Gross Profit ($M) | C11: 2733 | D11: 3457 | E11: 4380 | F11: 5756 | G11: Blended GM: 48.8% (FY22) → 49.8% (FY25)
B12: Gross Margin % | C12: 0.488 | D12: 0.49 | E12: 0.493 | F12: 0.498
B13: Sales & Marketing ($M) | C13: 895 | D13: 888 | E13: 1043 | F13: 1422 | G13: Non-GAAP (excl. SBC)
B14: Research & Development ($M) | C14: 810 | D14: 729 | E14: 1155 | F14: 1244 | G14: Reduced post-2022 workforce restructuring
B15: General & Administrative ($M) | C15: 806 | D15: 840 | E15: 599 | F15: 1080 | G15: Non-GAAP
B16: Total Operating Expenses ($M) | C16: 2511 | D16: 2457 | E16: 2797 | F16: 3746 | G16: Sum S&M + R&D + G&A (non-GAAP)
B17: EBITDA (adj.) ($M) | C17: 44 | D17: 813 | E17: 1509 | F17: 1996 | G17: Non-GAAP adj. EBITDA; source: earnings releases + GS/JPM
B18: EBITDA Margin % | C18: 0.008 | D18: 0.115 | E18: 0.17 | F18: 0.173
B19: D&A ($M) | C19: 200 | D19: 235 | E19: 265 | F19: 310 | G19: Approximate; ~3.6% → 2.7% of revenue
B20: EBIT ($M) | C20: 22 | D20: 765 | E20: 1318 | F20: 1700 | G20: EBITDA minus D&A
B21: Interest Income/(Expense) ($M) | C21: -85 | D21: -195 | E21: -232 | F21: -295 | G21: Net interest income (Shopify has net cash position)
B22: EBT ($M) | C22: 107 | D22: 960 | E22: 1550 | F22: 1995
B23: Tax ($M) | C23: 16 | D23: 144 | E23: 233 | F23: 299 | G23: Effective rate ~15% on adj. basis
B24: Net Income (adj.) ($M) | C24: 91 | D24: 816 | E24: 1317 | F24: 1696 | G24: Adj. net income (non-GAAP)
B26: BALANCE SHEET (KEY ITEMS)
B27: Cash & Equivalents ($M) | C27: 5053 | D27: 5008 | E27: 5479 | F27: 5778 | G27: Q4 balance; FY2025 cash per Q1'26 BS
B28: Total Debt ($M) | C28: 913 | D28: 916 | E28: 0 | F28: 0 | G28: $913M conv. notes repaid FY2024; $0 thereafter
B29: Net Debt ($M) [neg = net cash] | C29: -4140 | D29: -4092 | E29: -5479 | F29: -5778 | G29: Negative = net cash
B30: Total Assets ($M) | C30: 9500 | D30: 10900 | E30: 12800 | F30: 16200 | G30: Total assets per annual 10-K
B32: CASH FLOW (KEY ITEMS)
B33: Operating Cash Flow ($M) | C33: -136 | D33: 944 | E33: 1616 | F33: 2033 | G33: OCF = FCF + Capex
B34: Capex ($M) | C34: 50 | D34: 39 | E34: 19 | F34: 26 | G34: ~1.8% of revenue; primarily technology infrastructure
B35: Free Cash Flow ($M) | C35: -186 | D35: 905 | E35: 1597 | F35: 2007 | G35: FCF = OCF - Capex; FY2022: -$186M (growth investment); FY2025A $2,007M (17.4%)

Sheet FINANCIAL MODEL
B2: Financial Model — Shopify Historical & Projections
B4: Line Item ($M) | C4: FY2022 | D4: FY2023 | E4: FY2024 | F4: FY2025A | G4: FY2026E | H4: FY2027E | I4: FY2028E | J4: FY2029E | K4: FY2030E | L4: Notes
B5: Projection Assumptions (Yellow = change for scenario analysis)
B6: FY2026E–FY2030E assumptions driven by consensus estimates + IC memo thesis.
B7: Revenue Growth % | G7: 0.282 | H7: 0.232 | I7: 0.212 | J7: 0.2 | K7: FY2026E: +28.2% (model); decel to +18% by FY2030E | L7: FY2026E: +29% (consensus); decel to +18% by FY2030E
B8: Gross Margin % | G8: 0.5 | H8: 0.505 | I8: 0.51 | J8: 0.515 | K8: 0.52 | L8: 50.0%–52.0%; modest Sub mix uplift
B9: S&M % of Revenue | G9: 0.125 | H9: 0.12 | I9: 0.118 | J9: 0.115 | K9: 0.112 | L9: 12.5% → 11.2%; OpEx leverage on scale
B10: R&D % of Revenue | G10: 0.113 | H10: 0.115 | I10: 0.115 | J10: 0.113 | K10: 0.11 | L10: 11.3% → 11.0%; AI capex partially capitalised
B11: G&A % of Revenue | G11: 0.075 | H11: 0.076 | I11: 0.077 | J11: 0.075 | K11: 0.073 | L11: 7.5% → 7.3%; fixed overhead scale benefit
B12: D&A % of Revenue | G12: 0.028 | H12: 0.027 | I12: 0.026 | J12: 0.025 | K12: 0.024 | L12: 2.8% → 2.4%; intangible amortisation declining
B13: Tax Rate % | G13: 0.15 | H13: 0.15 | I13: 0.15 | J13: 0.15 | K13: 0.15 | L13: 15% effective; SBC deductions + R&D credits
B14: Capex % of Revenue | G14: 0.017 | H14: 0.016 | I14: 0.015 | J14: 0.015 | K14: 0.014 | L14: 1.7% → 1.4%; lean capex model
B16: Income Statement
B17: Revenue | C17: 5595 | D17: 7061 | E17: 8884 | F17: 11556 | G17: =F17*(1+G7) | H17: =G17*(1+H7) | I17: =H17*(1+I7) | J17: =I17*(1+J7) | K17: =J17*(1+K7) | L17: Q1'26A $3,170M (+34% YoY); FY2026E consensus $14,885M (+29%)
B18: YoY Growth % | D18: 0.262 | E18: 0.258 | F18: 0.302 | G18: =IFERROR(G17/F17-1,"-") | H18: =IFERROR(H17/G17-1,"-") | I18: =IFERROR(I17/H17-1,"-") | J18: =IFERROR(J17/I17-1,"-") | K18: =IFERROR(K17/J17-1,"-")
B19: Gross Profit | C19: 2733 | D19: 3457 | E19: 4380 | F19: 5756 | G19: =G17*G8 | H19: =H17*H8 | I19: =I17*I8 | J19: =J17*J8 | K19: =K17*K8 | L19: Sub Solutions ~80% GM; Merchant Solutions ~38% GM; blended expands
B20: Gross Margin % | C20: 0.488 | D20: 0.49 | E20: 0.493 | F20: 0.498 | G20: =IFERROR(G19/G17,"-") | H20: =IFERROR(H19/H17,"-") | I20: =IFERROR(I19/I17,"-") | J20: =IFERROR(J19/J17,"-") | K20: =IFERROR(K19/K17,"-")
B21: Sales & Marketing | C21: 895 | D21: 888 | E21: 1043 | F21: 1422 | G21: =G17*G9 | H21: =H17*H9 | I21: =I17*I9 | J21: =J17*J9 | K21: =K17*K9
B22: Research & Development | C22: 810 | D22: 729 | E22: 1155 | F22: 1244 | G22: =G17*G10 | H22: =H17*H10 | I22: =I17*I10 | J22: =J17*J10 | K22: =K17*K10 | L22: AI/Sidekick investment headwind ~FY2026–27
B23: General & Administrative | C23: 806 | D23: 840 | E23: 599 | F23: 1080 | G23: =G17*G11 | H23: =H17*H11 | I23: =I17*I11 | J23: =J17*J11 | K23: =K17*K11
B24: Total OpEx | C24: 2511 | D24: 2457 | E24: 2797 | F24: 3746 | G24: =G21+G22+G23 | H24: =H21+H22+H23 | I24: =I21+I22+I23 | J24: =J21+J22+J23 | K24: =K21+K22+K23 | L24: Q1'26 OpEx/Rev = 32%; target 28% by FY2030E via operating leverage
B25: EBITDA (adj.) | C25: 44 | D25: 813 | E25: 1509 | F25: 1996 | G25: =G19-G24 | H25: =H19-H24 | I25: =I19-I24 | J25: =J19-J24 | K25: FY2025A 17.3% (model); FY2026E ~18.8%; FY2028E ~21.2% | L25: FY2025A 17.4%; FY2026E ~18.7% consensus; FY2028E base ~20%
B26: EBITDA Margin % | C26: 0.008 | D26: 0.115 | E26: 0.17 | F26: 0.173 | G26: =IFERROR(G25/G17,"-") | H26: =IFERROR(H25/H17,"-") | I26: =IFERROR(I25/I17,"-") | J26: =IFERROR(J25/J17,"-") | K26: =IFERROR(K25/K17,"-")
B27: D&A | C27: 200 | D27: 235 | E27: 265 | F27: 310 | G27: =G17*G12 | H27: =H17*H12 | I27: =I17*I12 | J27: =J17*J12 | K27: =K17*K12
B28: EBIT | C28: 22 | D28: 765 | E28: 1318 | F28: 1700 | G28: =G25-G27 | H28: =H25-H27 | I28: =I25-I27 | J28: =J25-J27 | K28: =K25-K27
B29: Interest Income/(Expense) | C29: -85 | D29: -195 | E29: -232 | F29: -295 | L29: Shopify earns net interest on ~$6-9B cash; model as income (negative expense)
B30: EBT | C30: 107 | D30: 960 | E30: 1550 | F30: 1995 | G30: =G28-G29 | H30: =H28-H29 | I30: =I28-I29 | J30: =J28-J29 | K30: =K28-K29
B31: Tax | C31: 16 | D31: 144 | E31: 233 | F31: 299 | G31: =G30*G13 | H31: =H30*H13 | I31: =I30*I13 | J31: =J30*J13 | K31: =K30*K13 | L31: ~15% effective adj. rate; SBC deductions support
B32: Net Income (adj.) | C32: 91 | D32: 816 | E32: 1317 | F32: 1696 | G32: =G30-G31 | H32: =H30-H31 | I32: =I30-I31 | J32: =J30-J31 | K32: =K30-K31
B34: Free Cash Flow
B35: EBITDA (adj.) | G35: =G25 | H35: =H25 | I35: =I25 | J35: =J25 | K35: =K25
B36: Less: Capex | C36: 50 | D36: 39 | E36: 19 | F36: 26 | G36: =G17*G14 | H36: =H17*H14 | I36: =I17*I14 | J36: =J17*J14 | K36: =K17*K14 | L36: ~1.7%→1.4% of rev; technology infrastructure + office
B37: Less: Interest & Other | L37: Leave blank; interest income captured in NI above
B38: Free Cash Flow | C38: -186 | D38: 905 | E38: 1597 | F38: 2007 | G38: =G25-G36-G37 | H38: =H25-H36-H37 | I38: =I25-I36-I37 | J38: =J25-J36-J37 | K38: FY2022: -$186M; FY2025A $2,007M (17.4%); FY2028E $4,274M (19.3%) | L38: FY2025A $2,007M (17.4%); FY2026E ~$2,610M cons (17.5%); FY2028E ~$4.1B target
B40: Shopify-Specific KPIs (Supplemental)
B41: GMV ($B) | C41: 197.3 | D41: 235.9 | E41: 292.3 | F41: 378.4 | G41: 477.8 | H41: 583 | I41: 699.6 | J41: 871 | K41: Model FY2025A $378.4B (+29% YoY); FY2028E $699.6B (+20%) | L41: Q1'26A: $100.7B (+35%); FY2025A ~$329B (+23%)
B42: GPV Penetration % of GMV | C42: 0.561 | D42: 0.6 | E42: 0.643 | F42: 0.68 | G42: 0.71 | H42: 0.75 | I42: 0.79 | J42: 0.73 | K42: GPV% FY2025A: 68%; FY2026E: 71%; FY2028E: 79% (model) | L42: Q1'26A: 67%; targeting 72%+ by FY2028
B43: Merchant Solutions Rev/GMV (Take Rate) | C43: 0.0208 | D43: 0.0221 | E43: 0.0223 | F43: 0.0233 | G43: 0.0241 | H43: 0.025 | I43: 0.0259 | J43: 0.025 | K43: Attach rate FY2025A: 2.33%; FY2028E: 2.59% (model) | L43: Q1'26A: 2.40% (+7bps YoY)
B44: MRR ($M) | C44: 109.5 | D44: 144 | E44: 178 | F44: 205 | G44: 239 | H44: 267 | I44: 291 | J44: 340 | K44: MRR FY2025A: $205M; FY2026E: $239M; FY2028E: $291M (model) | L44: Q1'26A: $212M (+16% YoY); Plus ~28% of MRR

Sheet KPI TREE
B2: KPI Tree — Shopify Management Plan Audit
B4: FY2026E Budget = Street consensus (May 2026). Actual = Q1'26A annualised or FY2025A. Green = on track. Orange = watch. Red = behind plan.
B6: Lvl | C6: KPI Name | D6: Category | E6: Financial Model Line | F6: Frequency | G6: FY2026E Budget | H6: FY2025A Actual | I6: Variance ($) | J6: Variance % | K6: Status | L6: Notes
B7: NS | C7: NORTH STAR — GMV ($B) | D7: Scale | F7: Quarterly | G7: ='FINANCIAL MODEL'!G41 | H7: ='FINANCIAL MODEL'!F41 | I7: =IFERROR(H7-G7,"-") | J7: =IFERROR(I7/G7,"-") | K7: =IFERROR(IF((H7-G7)/G7>-0.05,"On Track",IF((H7-G7)/G7>-0.15,"Watch","Behind Plan")),"-") | L7: Q1'26A: $100.7B (+35%); FY2026E: $489B consensus
B8: 1 | C8: Total Revenue ($M) | D8: Growth | F8: Monthly | G8: ='FINANCIAL MODEL'!G17 | H8: ='FINANCIAL MODEL'!F17 | I8: =IFERROR(H8-G8,"-") | J8: =IFERROR(I8/G8,"-") | K8: =IFERROR(IF((H8-G8)/G8>-0.05,"On Track",IF((H8-G8)/G8>-0.15,"Watch","Behind Plan")),"-") | L8: Q1'26A: $3,170M (+34%); consensus $14.9B
B9: 2 | C9: Subscription Solutions ($M) | D9: Growth | F9: Monthly | G9: 3440 | H9: 2752 | I9: =IFERROR(H9-G9,"-") | J9: =IFERROR(I9/G9,"-") | K9: =IFERROR(IF((H9-G9)/G9>-0.05,"On Track",IF((H9-G9)/G9>-0.15,"Watch","Behind Plan")),"-") | L9: Q1'26A: $750M (+21%); 23% of Q1 rev
B10: 2 | C10: Merchant Solutions ($M) | D10: Growth | F10: Monthly | G10: 11445 | H10: 8804 | I10: =IFERROR(H10-G10,"-") | J10: =IFERROR(I10/G10,"-") | K10: =IFERROR(IF((H10-G10)/G10>-0.05,"On Track",IF((H10-G10)/G10>-0.15,"Watch","Behind Plan")),"-") | L10: Q1'26A: $2,420M (+39%); 77% of Q1 rev
B11: 2 | C11: MRR ($M) | D11: Growth | F11: Monthly | G11: ='FINANCIAL MODEL'!G44 | H11: ='FINANCIAL MODEL'!F44 | I11: =IFERROR(H11-G11,"-") | J11: =IFERROR(I11/G11,"-") | K11: =IFERROR(IF((H11-G11)/G11>-0.05,"On Track",IF((H11-G11)/G11>-0.15,"Watch","Behind Plan")),"-") | L11: Q1'26A: $212M (+16%); Plus ~28%
B12: 1 | C12: Blended Gross Margin | D12: Margin | F12: Monthly | G12: ='FINANCIAL MODEL'!G8 | H12: =IFERROR('FINANCIAL MODEL'!F19/'FINANCIAL MODEL'!F17,"-") | I12: =IFERROR(H12-G12,"-") | J12: =IFERROR(I12/G12,"-") | K12: =IFERROR(IF((H12-G12)/G12>-0.05,"On Track",IF((H12-G12)/G12>-0.15,"Watch","Behind Plan")),"-") | L12: Q1'26A: 48.8%; modest improvement expected
B13: 2 | C13: Sub Solutions Gross Margin | D13: Margin | F13: Monthly | G13: 0.8 | H13: 0.8 | I13: =IFERROR(H13-G13,"-") | J13: =IFERROR(I13/G13,"-") | K13: =IFERROR(IF((H13-G13)/G13>-0.05,"On Track",IF((H13-G13)/G13>-0.15,"Watch","Behind Plan")),"-") | L13: AI/LLM cost headwind; -10bps YoY in Q1'26
B14: 2 | C14: Merchant Solutions Gross Margin | D14: Margin | F14: Monthly | G14: 0.38 | H14: 0.375 | I14: =IFERROR(H14-G14,"-") | J14: =IFERROR(I14/G14,"-") | K14: =IFERROR(IF((H14-G14)/G14>-0.05,"On Track",IF((H14-G14)/G14>-0.15,"Watch","Behind Plan")),"-") | L14: Payments mix increasing; take rate expanding
B15: 1 | C15: Adj. EBITDA Margin | D15: Margin | F15: Monthly | G15: ='FINANCIAL MODEL'!G26 | H15: ='FINANCIAL MODEL'!F26 | I15: =IFERROR(H15-G15,"-") | J15: =IFERROR(I15/G15,"-") | K15: =IFERROR(IF((H15-G15)/G15>-0.05,"On Track",IF((H15-G15)/G15>-0.15,"Watch","Behind Plan")),"-") | L15: Q1'26A: 16.5% (adj.); opex leverage continues
B16: 2 | C16: S&M % of Revenue | D16: Efficiency | F16: Monthly | G16: ='FINANCIAL MODEL'!G9 | H16: 0.123 | I16: =IFERROR(H16-G16,"-") | J16: =IFERROR(I16/G16,"-") | K16: =IFERROR(IF((H16-G16)/G16>-0.05,"On Track",IF((H16-G16)/G16>-0.15,"Watch","Behind Plan")),"-") | L16: Q1'26A: ~12.1%
B17: 2 | C17: R&D % of Revenue | D17: Efficiency | F17: Monthly | G17: ='FINANCIAL MODEL'!G10 | H17: 0.108 | I17: =IFERROR(H17-G17,"-") | J17: =IFERROR(I17/G17,"-") | K17: =IFERROR(IF((H17-G17)/G17>-0.05,"On Track",IF((H17-G17)/G17>-0.15,"Watch","Behind Plan")),"-") | L17: AI/Sidekick investment increasing R&D as % rev
B18: 2 | C18: OpEx Total % of Revenue | D18: Efficiency | F18: Monthly | G18: =IFERROR('FINANCIAL MODEL'!G24/'FINANCIAL MODEL'!G17,"-") | H18: 0.324 | I18: =IFERROR(H18-G18,"-") | J18: =IFERROR(I18/G18,"-") | K18: =IFERROR(IF((H18-G18)/G18<0.05,"On Track",IF((H18-G18)/G18<0.15,"Watch","Behind Plan")),"-") | L18: Q1'26 = 32%; targeting 31% FY2026E
B19: 1 | C19: GMV Specific KPIs | D19: Growth | F19: Quarterly | I19: =IFERROR(H19-G19,"-") | J19: =IFERROR(I19/G19,"-") | K19: N/A
B20: 2 | C20: GPV Penetration % GMV | D20: Payments | F20: Quarterly | G20: ='FINANCIAL MODEL'!G42 | H20: ='FINANCIAL MODEL'!F42 | I20: =IFERROR(H20-G20,"-") | J20: =IFERROR(I20/G20,"-") | K20: =IFERROR(IF((H20-G20)/G20>-0.05,"On Track",IF((H20-G20)/G20>-0.15,"Watch","Behind Plan")),"-") | L20: Q1'26A: 67%; +200bps/yr trajectory
B21: 2 | C21: Payments Take Rate (GPV/Rev) | D21: Payments | F21: Quarterly | G21: ='FINANCIAL MODEL'!G43 | H21: ='FINANCIAL MODEL'!F43 | I21: =IFERROR(H21-G21,"-") | J21: =IFERROR(I21/G21,"-") | K21: =IFERROR(IF((H21-G21)/G21>-0.05,"On Track",IF((H21-G21)/G21>-0.15,"Watch","Behind Plan")),"-") | L21: Q1'26A: 2.40% (+7bps YoY)
B22: 2 | C22: B2B GMV Growth % | D22: Growth | F22: Quarterly | G22: 0.6 | I22: =IFERROR(H22-G22,"-") | J22: =IFERROR(I22/G22,"-") | K22: =IFERROR(IF((H22-G22)/G22>-0.05,"On Track",IF((H22-G22)/G22>-0.15,"Watch","Behind Plan")),"-") | L22: Q1'26A: +80% YoY; early-stage, pre-scale
B23: 2 | C23: International GMV Growth % | D23: Growth | F23: Quarterly | G23: 0.35 | I23: =IFERROR(H23-G23,"-") | J23: =IFERROR(I23/G23,"-") | K23: =IFERROR(IF((H23-G23)/G23>-0.05,"On Track",IF((H23-G23)/G23>-0.15,"Watch","Behind Plan")),"-") | L23: Q1'26A: +45% YoY; Europe +48%
B24: 1 | C24: Free Cash Flow ($M) | D24: Cash | F24: Monthly | G24: ='FINANCIAL MODEL'!G38 | H24: ='FINANCIAL MODEL'!F38 | I24: =IFERROR(H24-G24,"-") | J24: =IFERROR(I24/G24,"-") | K24: =IFERROR(IF((H24-G24)/G24>-0.05,"On Track",IF((H24-G24)/G24>-0.15,"Watch","Behind Plan")),"-") | L24: Q1'26A: $476M (15%); full-yr cons $2.6B (17.5%)
B25: 2 | C25: FCF Margin | D25: Cash | F25: Monthly | G25: =IFERROR('FINANCIAL MODEL'!G38/'FINANCIAL MODEL'!G17,"-") | H25: =IFERROR('FINANCIAL MODEL'!F38/'FINANCIAL MODEL'!F17,"-") | I25: =IFERROR(H25-G25,"-") | J25: =IFERROR(I25/G25,"-") | K25: =IFERROR(IF((H25-G25)/G25>-0.05,"On Track",IF((H25-G25)/G25>-0.15,"Watch","Behind Plan")),"-") | L25: Q2'26 guide: mid-teens (MCA reclass headwind)
B26: 2 | C26: Capex % Revenue | D26: Cash | F26: Monthly | G26: ='FINANCIAL MODEL'!G14 | H26: 0.017 | I26: =IFERROR(H26-G26,"-") | J26: =IFERROR(I26/G26,"-") | K26: =IFERROR(IF((H26-G26)/G26<0.05,"On Track",IF((H26-G26)/G26<0.15,"Watch","Behind Plan")),"-") | L26: Lean capex model maintained

Sheet MOIC BRIDGE
B2: MOIC Bridge — Shopify Entry to Exit (FY2028E Base)
B4: Equity value waterfall from entry ($108/share) to exit (FY2028E base). NTB contributions pull from NTB Registry (incremental EV if NTB confirmed). Note: Shopify is a public equity long; MOIC reflects total return, not PE carry.
B6: Component | C6: Equity Value ($M) | D6: MOIC Contribution | E6: Cumulative MOIC
B7: Entry Equity Invested ($108/share × 1,307M) | C7: =INPUTS!C21 | D7: 1 | E7: =IFERROR(INPUTS!C21/INPUTS!C21,"-")
B8: NTB-1: GMV Sustains 25%+ Through FY2027 | C8: =IFERROR('NTB REGISTRY'!F8,"-") | D8: =IFERROR('NTB REGISTRY'!G8,"-") | E8: =IFERROR(E7+D8,"-")
B9: NTB-2: Payments GPV Penetration to 70%+ | C9: =IFERROR('NTB REGISTRY'!F9,"-") | D9: =IFERROR('NTB REGISTRY'!G9,"-") | E9: =IFERROR(E8+D9,"-")
B10: NTB-3: AI Commerce Net Revenue-Positive | C10: =IFERROR('NTB REGISTRY'!F10,"-") | D10: =IFERROR('NTB REGISTRY'!G10,"-") | E10: =IFERROR(E9+D10,"-")
B11: NTB-4: Enterprise Plus Margin Durable | C11: =IFERROR('NTB REGISTRY'!F11,"-") | D11: =IFERROR('NTB REGISTRY'!G11,"-") | E11: =IFERROR(E10+D11,"-")
B12: NTB-5: FCF Margin Expands to 20%+ | C12: =IFERROR('NTB REGISTRY'!F12,"-") | D12: =IFERROR('NTB REGISTRY'!G12,"-") | E12: =IFERROR(E11+D12,"-")
B13: NTB-6: Macro Does Not Materially Deteriorate | C13: =IFERROR('NTB REGISTRY'!F13,"-") | D13: =IFERROR('NTB REGISTRY'!G13,"-") | E13: =IFERROR(E12+D13,"-")
B14: Multiple Re-rating / Compression (net) | E14: =IFERROR(E13+D14,"-")
B16: Exit Proceeds to Equity (FY2028E Base: 45x × $4.49B EBITDA + $8.5B net cash) | C16: =INPUTS!C30 | D16: =IFERROR(INPUTS!C30/INPUTS!C21,"-") | E16: =IFERROR(INPUTS!C30/INPUTS!C21,"-")

Sheet DRIVER TREE
B1: DRIVER TREE · SHOPIFY DEAL WORKBOOK
B2: Revenue driver decomposition → EBITDA cascade → EV/MOIC attribution | Entry: FY2026E | Exit: FY2028E | Entry Multiple: 48.5× | Exit Multiple: 45.0×
B3: Decomposition: GMV volume (at entry attach rate) + attach rate improvement (at exit GMV). EBITDA impact uses segment incremental margins calibrated to model. EV impact uses entry multiple (Paasche). Sources: [Model] = model.xlsx, [IC Memo] = Shopify IC Memo v2, [Analyst] = analyst allocation.
B5: REVENUE DRIVER DECOMPOSITION → EBITDA → EV → MOIC
B6: Driver | C6: Source | D6: KPI Metric | E6: Unit | F6: FY2025A | G6: FY2026E (Entry) | H6: FY2028E (Exit) | I6: Δ (28E–26E) | J6: Revenue Impact ($M) | K6: Incr. EBITDA % | L6: EBITDA Impact ($M) | M6: EV Impact ($M, ×48.5) | N6: MOIC Delta (×)
B7: MERCHANT SOLUTIONS REVENUE | F7: $M | G7: 11513 | H7: 18115 | I7: 6602
B8: GMV Growth → Volume Effect | D8: GMV growth × entry attach rate (240.9 bps)
B9: Same-Cohort Productivity | C9: Analyst | D9: Existing merchant GMV expansion (40% alloc.) | E9: $B | F9: 151.376 | G9: 191.135 | H9: 279.822 | I9: 88.687 | J9: 2136.465 | K9: 0.214 | L9: 457.138 | M9: 22171.171 | N9: 0.157
B10: New Merchant Acquisition | C10: Analyst | D10: Net new merchant cohort GMV (30% alloc.) | E10: $B | F10: 113.532 | G10: 143.351 | H10: 209.866 | I10: 66.515 | J10: 1602.349 | K10: 0.214 | L10: 342.853 | M10: 16628.378 | N10: 0.117
B11: Geographic Expansion (International) | C11: IC Memo | D11: International GMV (Europe, LatAm, Asia) — +45% YoY Q1'26 (20% alloc.) | E11: $B | F11: 75.688 | G11: 95.568 | H11: 139.911 | I11: 44.343 | J11: 1068.233 | K11: 0.214 | L11: 228.569 | M11: 11085.585 | N11: 0.078
B12: B2B / POS / Channel Expansion | C12: IC Memo | D12: B2B GMV (+80% Q1'26), Offline POS (+33%), Shop App (10% alloc.) | E12: $B | F12: 37.844 | G12: 47.784 | H12: 69.956 | I12: 22.172 | J12: 534.116 | K12: 0.214 | L12: 114.284 | M12: 5542.793 | N12: 0.039
B13: Subtotal: GMV Volume Effect | I13: 221.7 | J13: 5341.163 | K13: 0.214 | L13: 1142.844 | M13: 55427.927 | N13: 0.392
B14: Attach Rate Improvement | D14: Attach rate (bps) improvement × FY2028E GMV of $699.6B
B15: GPV Penetration (71% → 79%) | C15: Model + IC Memo | D15: Shopify Payments GPV% — 100bps = $124M revenue at exit GMV | E15: % | F15: 68 | G15: 71 | H15: 79 | I15: 8 | J15: 990.806 | K15: 0.214 | L15: 212.002 | M15: 10282.088 | N15: 0.073
B16: Non-Payments Attach (MCA, Balance, Markets) | C16: Model | D16: Shopify Capital, Balance, Markets — incremental bps at exit GMV | E16: bps | F16: 0 | G16: 0 | H16: 0 | I16: 16.6 | J16: 268.393 | K16: 0.214 | L16: 57.428 | M16: 2785.253 | N16: 0.02
B17: Subtotal: Attach Rate Improvement | G17: 240.9 | H17: 258.9 | I17: 18 | J17: 1259.199 | K17: 0.214 | L17: 269.43 | M17: 13067.341 | N17: 0.092
B18: TOTAL: Merchant Solutions Revenue | C18: Model | E18: $M | G18: 11513 | H18: 18115 | I18: 6602 | J18: 6602 | K18: 0.214 | L18: 1412.274 | M18: 68495.268 | N18: 0.484
B20: SUBSCRIPTION SOLUTIONS REVENUE | F20: $M | G20: 3305 | H20: 4023 | I20: 718
B21: MRR Build: Revenue = MRR × 13.8× (implied annual multiplier; model MRR × 12 + deferred revenue adj.)
B22: Plus / Enterprise MRR Growth | C22: Model | D22: Plus MRR ($M) — enterprise cohort (≥$25M GMV, fastest-growing Q1'26) | E22: $M MRR | F22: 69.7 | G22: 83.6 | H22: 114.5 | I22: 30.9 | J22: 426.942 | K22: 0.676 | L22: 288.617 | M22: 13997.943 | N22: 0.099
B23: Core SMB MRR Growth | C23: Model | D23: Core MRR ($M) — basic/standard/advanced plan merchants | E23: $M MRR | F23: 135.3 | G23: 155.6 | H23: 176.4 | I23: 20.8 | J23: 287.391 | K23: 0.676 | L23: 194.28 | M23: 9422.564 | N23: 0.067
B24: TOTAL: Subscription Solutions Revenue | C24: Model | E24: $M | G24: 3305 | H24: 4023 | I24: 718 | J24: 718 | K24: 0.676 | L24: 485.376 | M24: 23540.729 | N24: 0.166
B26: TOTAL REVENUE GROWTH | C26: Model | E26: $M | G26: 14818 | H26: 22138 | I26: 7320 | J26: 7320 | K26: 0.259 | L26: 1897.649 | M26: 92035.997 | N26: 0.65
B28: VALUE CREATION BRIDGE (Reconciliation: Revenue Drivers + Multiple Compression + Net Cash)
B29: Bridge Component | F29: FY2026E | H29: FY2028E | J29: EBITDA Effect ($M) | K29: × | L29: EV Impact ($M) | M29: MOIC Impact (×)
B30: Revenue-Driven EBITDA Growth (×48.5 entry multiple) | J30: 1897.649 | K30: 48.5 | L30: 92035.997 | N30: 0.65
B31: Multiple Compression (48.5× → 45.0×) × Exit EBITDA $4,687M | J31: -16404.5 | K31: 1 | L31: -16404.5 | N31: -0.116
B32: Net Cash Build (Net Cash $6.3B → $12.4B) | J32: 6115 | K32: 1 | L32: 6115 | N32: 0.043
B33: TOTAL VALUE CREATION (Entry Equity → Exit Proceeds) | J33: -14506.85 | L33: 81746.5 | N33: 0.58
B34: MOIC CHECK (1.0× invested capital + attribution) | N34: 1.577
B36: Assumptions: GMV sub-driver allocations (same-cohort 40%, new merchant 30%, geographic 20%, B2B/channel 10%) are analyst estimates based on IC Memo Pillars 1-2. GPV penetration revenue = IC Memo disclosure ($67M per 100bps at FY2025A GMV) scaled to exit GMV. Incr. EBITDA margins: Merchant ~21.4% (37.7% seg. GM − ~16.3% opex allocation), Sub ~67.6% (82.0% seg. GM − 14.4% opex). EV computed using entry multiple (48.5×) per Paasche decomposition; total value creation reconciles to INPUTS!C59.

Sheet NTB REGISTRY
B1: NTB REGISTRY · SHOPIFY DEAL WORKBOOK
B2: Investment thesis mapped to revenue drivers → EBITDA → EV → MOIC attribution. Base = model FY2028E. Upside = IC Memo bull case.
B3: Source: IC Memo v2 Pillars 1-4 mapped to DRIVER TREE. Base EV uses Paasche decomposition (×48.5 entry multiple). Upside = analyst thesis above model.
B5: NTB REGISTRY — THESIS TO VALUE ATTRIBUTION
B6: NTB | C6: Theme | D6: Thesis Summary (Key Assumption vs. Consensus) | E6: Base EV Impact ($M) | F6: Base MOIC Delta (×) | G6: Upside EV ($M) | H6: Upside MOIC (×) | I6: IC Memo Pillar | J6: Driver Tree Rows | K6: Rating / Status
B7: NTB 1 | C7: GMV Flywheel | D7: Thesis: Multiple independent GMV growth vectors (same-cohort expansion, new merchant acquisition, geographic expansion to 15 intl markets, B2B +80% YoY) sustain 20-22% GMV CAGR through FY2028E vs. consensus expectation of GMV deceleration driven by FX and tougher comps. Key: geographic and B2B channels reduce single-point-of-failure risk. [IC Memo: Pillar 1 — LOW evidence strength, THESIS-CRITICAL] | E7: 55427.927 | F7: 0.392 | G7: 72056.306 | H7: 0.509 | I7: Pillar 1 | J7: Same-Cohort, New Merchant, Geographic, B2B/Channel | K7: OPEN — thesis-critical
B8: NTB 2 | C8: Payments Monetization | D8: Thesis: GPV penetration grows 71% → 79% FY2026-28E driven by Shop Pay expansion on non-Shopify storefronts, checkout optimization, and merchant incentives. Each 100bps penetration = $124M incremental revenue at exit GMV ($699.6B). Model assumes 8pp penetration gain; consensus (sell-side avg) ~74% FY2028E implies 5pp below model — model is already thesis-aligned. Non-payments (MCA, Balance) add $268M incremental. [IC Memo: Pillar 2 — HIGH evidence strength, Payments thesis CONFIRMED] | E8: 13067.341 | F8: 0.092 | G8: 18294.277 | H8: 0.129 | I8: Pillar 2 | J8: GPV Penetration, Non-Payments Attach | K8: CONFIRMED — HIGH evidence
B9: NTB 3 | C9: AI Commerce Platform (Optionality) | D9: Thesis: Shopify's 20+ year proprietary commerce data creates a structural moat vs. general-purpose AI (2× conversion rate on AI-assisted orders vs. organic search Q1'26). AI revenue streams (Sidekick subscription, Usage-based Commerce Protocols) not yet in base model — pure optionality upside. No FY2028E base case contribution modeled. Upside scenario: $40B EV ($15B Sidekick + $25B UCP). [IC Memo: Pillar 3 — MEDIUM evidence strength, THESIS-CRITICAL for long-term] | E9: 0 | F9: 0 | G9: 40000 | H9: 0.283 | I9: Pillar 3 | J9: AI Sidekick (C1), AI UCP (C3) — upside only | K9: OPEN — hypothesis, not in model
B10: NTB 4 | C10: Enterprise Upmarket | D10: Thesis: $25M+ GMV cohort is fastest-growing segment Q1'26 with no SMB cannibalization. Plus MRR grows from $83.6M (FY2026E, 35% of MRR) to $114.5M (FY2028E, 39% of MRR) driving $427M incremental subscription revenue at ~82% gross margin. High-margin subscription mix shift benefits blended margins. Upside: Plus penetration accelerates to 45% of MRR ($137M) by FY2028E. [IC Memo: Pillar 4 — MEDIUM evidence strength, VALUATION OPTIONALITY] | E10: 23420.507 | F10: 0.165 | G10: 31617.684 | H10: 0.223 | I10: Pillar 4 | J10: Plus/Enterprise MRR, Core SMB MRR | K10: WATCH — valuation optionality
B11: NTB 5 | C11: Multiple Compression (Risk) | D11: Risk: Entry at 48.5× EV/EBITDA creates structural headwind. Exit at 45× already assumes compression. Each 1× turn of additional compression = $4,687M additional EV reduction = -0.033x MOIC drag. Downside scenario: exit at 40× → additional -$23.4B EV → MOIC = 1.41× (vs. 1.58× base). Offsetting factor: EBITDA growth nearly triples ($2.79B → $4.69B), supporting multiple. [Macro risk: consumer softness, tariff impact on SMB GMV] | E11: -16404.5 | F11: -0.116 | G11: -8202.25 | H11: -0.058 | I11: Macro / Risk | J11: Multiple Compression, Macro Consumer Risk | K11: STRUCTURAL — mitigant: EBITDA growth
B12: TOTAL | C12: Base + Multiple Compression + Net Cash | E12: 81626.27 | F12: 0.58
B13: MOIC CHECK | C13: =1.00× invested capital + total attribution (should = 1.58×) | F13: 1.577
