Workbook

Sheet README
A1: GTM Metrics Analyzer
A2: Input Template + Metric Calculator · B2B SaaS / GTM-Driven Businesses
A4: Purpose
A5: Use this workbook to load raw company data into Input_Fields, then review derived GTM metric calculations in Metric_Calcs, and surface a clean diagnostic summary in Diagnostic_Output. Supports all six GTM metric families: Growth Drivers, Sales Funnel, Retention, Efficiency & Economics, Team & Productivity, and Fiscal Maturity.
A7: How to Use
A8: 1. Input_Fields → Populate the User Value column (column F) with values from uploaded source files. Do not overwrite raw exports — add them as separate tabs if needed.
A9: 2. Metric_Calcs → Review formulas, required inputs, and calculated values. Column G auto-calculates from Input_Fields.
A10: 3. Diagnostic_Output → Clean summary of the 20 most decision-useful GTM metrics, pulled automatically from Metric_Calcs.
A11: 4. Do not modify column B (Input Key) or column B of Metric_Calcs (Metric Key) — these are the XLOOKUP lookup arrays.
A13: Requirements
A14: ⚠️ Requires Excel 365 or Excel 2021+. Formulas use XLOOKUP and FILTER, which are not available in older Excel versions or Google Sheets without modification.
A16: Metric Families
A17: Growth Drivers | B17: 7 metrics · Gross/Net New ARR, ARR Growth, Mix
A18: Sales Funnel | B18: 6 metrics · Pipeline Coverage, Win Rate, Close Rate, Forecast
A19: Retention | B19: 10 metrics · NDR, GDR, Logo Retention, Adoption, NPS, CSAT
A20: Efficiency & Economics | B20: 9 metrics · Gross Margin, Magic Number, CAC, LTV, Payback
A21: Team & Productivity | B21: 10 metrics · Sales Capacity, Attainment, Ramp Rate, FTE Productivity
A22: Fiscal Maturity | B22: 6 metrics · Plan Attainment, YoY Growth, FCF, Beat vs Guidance

Sheet Input_Fields
A1: Section | B1: Input Key | C1: Input Label | D1: Definition / What to Upload | E1: Input Requirement | F1: User Value | G1: Notes
A2: Company & Reporting Context | B2: business_model | C2: Business Model | D2: e.g., B2B SaaS, usage-based SaaS, hybrid, PLG, SLG | E2: Required
A3: Company & Reporting Context | B3: primary_revenue_metric | C3: Primary Revenue Metric | D3: ARR, MRR, CARR, bookings, billings, GAAP revenue | E3: Required
A4: Company & Reporting Context | B4: reporting_cadence | C4: Reporting Cadence | D4: Monthly, quarterly, annual, or LTM | E4: Required
A5: Company & Reporting Context | B5: analysis_period | C5: Analysis Period | D5: Period being analyzed | E5: Required
A6: Company & Reporting Context | B6: segment_scheme | C6: Segmentation Scheme | D6: SMB, MM, Enterprise, geo, product, channel, etc. | E6: Optional
A7: Revenue & ARR | B7: beginning_arr | C7: Beginning ARR | D7: ARR at start of period | E7: Required for ARR funnel | F7: 0
A8: Revenue & ARR | B8: new_logo_arr | C8: New Logo ARR | D8: ARR from new customers in period | E8: Required for ARR funnel | F8: 0
A9: Revenue & ARR | B9: expansion_arr | C9: Expansion ARR | D9: ARR expansion from existing customers | E9: Required for ARR funnel/retention | F9: 0
A10: Revenue & ARR | B10: upsell_arr | C10: Upsell ARR | D10: Expansion from same product / contract uplift | E10: Optional | F10: 0
A11: Revenue & ARR | B11: cross_sell_arr | C11: Cross-sell ARR | D11: Expansion from new product / contract | E11: Optional | F11: 0
A12: Revenue & ARR | B12: downsell_arr | C12: Downsell ARR | D12: ARR lost from customer downgrades | E12: Required for ARR funnel/retention | F12: 0
A13: Revenue & ARR | B13: logo_churn_arr | C13: Logo Churn ARR | D13: ARR lost from customer churn | E13: Required for ARR funnel/retention | F13: 0
A14: Revenue & ARR | B14: ending_arr | C14: Ending ARR | D14: ARR at end of period if already known | E14: Optional / validation | F14: 0
A15: Revenue & ARR | B15: bookings | C15: Bookings | D15: Total contract value signed in period | E15: Optional | F15: 0
A16: Revenue & ARR | B16: billings | C16: Billings | D16: Amount invoiced in period | E16: Optional | F16: 0
A17: Revenue & ARR | B17: revenue | C17: Revenue | D17: Recognized revenue in period | E17: Optional | F17: 0
A18: Revenue & ARR | B18: deferred_revenue | C18: Deferred Revenue | D18: Billings less recognized revenue | E18: Optional | F18: 0
... A73: Planning / Forecast | B73: plan_yoy_arr_growth_pct | C73: Plan YoY ARR Growth % | D73: Budgeted YoY ARR growth | E73: Optional | F73: 0
A74: Planning / Forecast | B74: actual_fcf | C74: Actual Free Cash Flow | D74: Optional | E74: 0
A75: Planning / Forecast | B75: plan_fcf | C75: Plan Free Cash Flow | D75: Optional | E75: 0
A76: Planning / Forecast | B76: revenue_guidance | C76: Revenue Guidance | D76: Management guidance | E76: Optional | F76: 0
A77: Planning / Forecast | B77: consensus_estimate | C77: Consensus Estimate | D77: Public-company context only | E77: Optional | F77: 0

Sheet Metric_Calcs
A1: Metric Family | B1: Metric Key | C1: Metric Name | D1: Type | E1: Formula / Logic | F1: Required Inputs | G1: Calculated Value | H1: Comments
A2: Growth Drivers | B2: gross_new_arr | C2: Gross New ARR | D2: Derived | E2: New Logo ARR + Expansion ARR | F2: new_logo_arr, expansion_arr | G2: =IF(COUNTIF(Input_Fields!$B:$B,"new_logo_arr")*COUNTIF(Input_Fields!$B:$B,"expansion_arr")=0,"",XLOOKUP("new_logo_arr",Input_Fields!$B:$B,Input_Fields!$F:$F,"")+XLOOKUP("expansion_arr",Input_Fields!$B:$B,Input_Fields!$F:$F,""))
A3: Growth Drivers | B3: churned_arr | C3: Churned ARR | D3: Derived | E3: Downsell ARR + Logo Churn ARR | F3: downsell_arr, logo_churn_arr | G3: =IF(COUNTIF(Input_Fields!$B:$B,"downsell_arr")*COUNTIF(Input_Fields!$B:$B,"logo_churn_arr")=0,"",XLOOKUP("downsell_arr",Input_Fields!$B:$B,Input_Fields!$F:$F,"")+XLOOKUP("logo_churn_arr",Input_Fields!$B:$B,Input_Fields!$F:$F,""))
A4: Growth Drivers | B4: net_new_arr | C4: Net New ARR | D4: Derived | E4: Gross New ARR - Churned ARR | F4: new_logo_arr, expansion_arr, downsell_arr, logo_churn_arr | G4: =IFERROR(G2-G3,"")
A5: Growth Drivers | B5: ending_arr_calc | C5: Ending ARR (Calculated) | D5: Derived | E5: Beginning ARR + Net New ARR | F5: beginning_arr, new_logo_arr, expansion_arr, downsell_arr, logo_churn_arr | G5: =IFERROR(XLOOKUP("beginning_arr",Input_Fields!$B:$B,Input_Fields!$F:$F,"")+G4,"")
A6: Growth Drivers | B6: arr_growth_yoy | C6: ARR Growth YoY % | D6: Derived | E6: ((EOP ARR / EOP ARR 12 months ago) - 1) * 100 | F6: Requires prior-year EOP ARR upload
A7: Growth Drivers | B7: new_logo_mix | C7: % Gross New ARR from New Logo | D7: Derived | E7: New Logo ARR / Gross New ARR | F7: new_logo_arr, expansion_arr | G7: =IFERROR(XLOOKUP("new_logo_arr",Input_Fields!$B:$B,Input_Fields!$F:$F,"")/G2,"")
A8: Growth Drivers | B8: expansion_mix | C8: % Gross New ARR from Expansion | D8: Derived | E8: Expansion ARR / Gross New ARR | F8: new_logo_arr, expansion_arr | G8: =IFERROR(XLOOKUP("expansion_arr",Input_Fields!$B:$B,Input_Fields!$F:$F,"")/G2,"")
A9: Sales Funnel | B9: pipeline_coverage | C9: Pipeline Coverage | D9: Derived | E9: Pipeline $ / Sales Target | F9: pipeline_dollars, sales_target | G9: =IFERROR(XLOOKUP("pipeline_dollars",Input_Fields!$B:$B,Input_Fields!$F:$F,"")/XLOOKUP("sales_target",Input_Fields!$B:$B,Input_Fields!$F:$F,""),"")
A10: Sales Funnel | B10: weighted_pipeline_coverage | C10: Weighted Pipeline Coverage | D10: Derived | E10: Weighted Pipeline $ / Sales Target | F10: weighted_pipeline_dollars, sales_target | G10: =IFERROR(XLOOKUP("weighted_pipeline_dollars",Input_Fields!$B:$B,Input_Fields!$F:$F,"")/XLOOKUP("sales_target",Input_Fields!$B:$B,Input_Fields!$F:$F,""),"")
A11: Sales Funnel | B11: win_rate | C11: Win Rate | D11: Derived | E11: Closed Won / (Closed Won + Closed Lost) | F11: closed_won_opportunities, closed_lost_opportunities | G11: =IFERROR(XLOOKUP("closed_won_opportunities",Input_Fields!$B:$B,Input_Fields!$F:$F,"")/(XLOOKUP("closed_won_opportunities",Input_Fields!$B:$B,Input_Fields!$F:$F,"")+XLOOKUP("closed_lost_opportunities",Input_Fields!$B:$B,Input_Fields!$F:$F,"")),"")
A12: Sales Funnel | B12: close_rate | C12: Close Rate | D12: Derived | E12: Closed Won in same period / Opportunities created in period | F12: closed_won_same_period, opportunities_created | G12: =IFERROR(XLOOKUP("closed_won_same_period",Input_Fields!$B:$B,Input_Fields!$F:$F,"")/XLOOKUP("opportunities_created",Input_Fields!$B:$B,Input_Fields!$F:$F,""),"")
A13: Sales Funnel | B13: sql_to_closed_won | C13: SQL to Closed Won | D13: Derived | E13: Closed Won SQLs / SQL Count | F13: closed_won_sql, sql_count | G13: =IFERROR(XLOOKUP("closed_won_sql",Input_Fields!$B:$B,Input_Fields!$F:$F,"")/XLOOKUP("sql_count",Input_Fields!$B:$B,Input_Fields!$F:$F,""),"")
A14: Sales Funnel | B14: forecast_pct_target | C14: Forecast as % of Sales Target | D14: Derived | E14: Forecast $ / Sales Target | F14: forecast_dollars, sales_target | G14: =IFERROR(XLOOKUP("forecast_dollars",Input_Fields!$B:$B,Input_Fields!$F:$F,"")/XLOOKUP("sales_target",Input_Fields!$B:$B,Input_Fields!$F:$F,""),"")
A15: Retention | B15: quarterly_ndr | C15: Quarterly Annualized NDR | D15: Derived | E15: 1 + ((Quarter Expansion ARR - Quarter Churned ARR) * 4) / avg(BOQ ARR + EOQ ARR) | F15: beginning_arr, ending_arr or calculated ending arr, expansion_arr, downsell_arr, logo_churn_arr | G15: =IFERROR(1+(((XLOOKUP("expansion_arr",Input_Fields!$B:$B,Input_Fields!$F:$F,"")-(XLOOKUP("downsell_arr",Input_Fields!$B:$B,Input_Fields!$F:$F,"")+XLOOKUP("logo_churn_arr",Input_Fields!$B:$B,Input_Fields!$F:$F,"")))*4)/AVERAGE(XLOOKUP("beginning_arr",Input_Fields!$B:$B,Input_Fields!$F:$F,""),IF(XLOOKUP("ending_arr",Input_Fields!$B:$B,Input_Fields!$F:$F,"")="",G5,XLOOKUP("ending_arr",Input_Fields!$B:$B,Input_Fields!$F:$F,"")))),"")
A16: Retention | B16: quarterly_gdr | C16: Quarterly Annualized GDR | D16: Derived | E16: 1 - (Quarter Gross Churned ARR * 4) / avg(BOQ ARR + EOQ ARR) | F16: beginning_arr, ending_arr or calculated ending arr, downsell_arr, logo_churn_arr | G16: =IFERROR(1-((((XLOOKUP("downsell_arr",Input_Fields!$B:$B,Input_Fields!$F:$F,"")+XLOOKUP("logo_churn_arr",Input_Fields!$B:$B,Input_Fields!$F:$F,""))*4)/AVERAGE(XLOOKUP("beginning_arr",Input_Fields!$B:$B,Input_Fields!$F:$F,""),IF(XLOOKUP("ending_arr",Input_Fields!$B:$B,Input_Fields!$F:$F,"")="",G5,XLOOKUP("ending_arr",Input_Fields!$B:$B,Input_Fields!$F:$F,"")))),"")
A17: Retention | B17: logo_retention | C17: Logo Retention | D17: Derived | E17: 1 - Churned Customers / avg(BOP Customers + EOP Customers) | F17: bop_customers, eop_customers, churned_customers | G17: =IFERROR(1-(XLOOKUP("churned_customers",Input_Fields!$B:$B,Input_Fields!$F:$F,"")/AVERAGE(XLOOKUP("bop_customers",Input_Fields!$B:$B,Input_Fields!$F:$F,""),XLOOKUP("eop_customers",Input_Fields!$B:$B,Input_Fields!$F:$F,""))),"")
A18: Retention | B18: logo_churn | C18: Logo Churn | D18: Derived | E18: Churned Customers / avg(BOP Customers + EOP Customers) | F18: bop_customers, eop_customers, churned_customers | G18: =IFERROR(XLOOKUP("churned_customers",Input_Fields!$B:$B,Input_Fields!$F:$F,"")/AVERAGE(XLOOKUP("bop_customers",Input_Fields!$B:$B,Input_Fields!$F:$F,""),XLOOKUP("eop_customers",Input_Fields!$B:$B,Input_Fields!$F:$F,"")),"")
A19: Retention | B19: dau_rate | C19: DAU Rate | D19: Derived | E19: DAU / Total Users | F19: dau, total_users | G19: =IFERROR(XLOOKUP("dau",Input_Fields!$B:$B,Input_Fields!$F:$F,"")/XLOOKUP("total_users",Input_Fields!$B:$B,Input_Fields!$F:$F,""),"")
A20: Retention | B20: mau_rate | C20: MAU Rate | D20: Derived | E20: MAU / Total Users | F20: mau, total_users | G20: =IFERROR(XLOOKUP("mau",Input_Fields!$B:$B,Input_Fields!$F:$F,"")/XLOOKUP("total_users",Input_Fields!$B:$B,Input_Fields!$F:$F,""),"")
A21: Retention | B21: adoption_rate | C21: Adoption Rate | D21: Derived | E21: Feature Active Users / Total Users | F21: feature_active_users, total_users | G21: =IFERROR(XLOOKUP("feature_active_users",Input_Fields!$B:$B,Input_Fields!$F:$F,"")/XLOOKUP("total_users",Input_Fields!$B:$B,Input_Fields!$F:$F,""),"")
A22: Retention | B22: stickiness_rate | C22: Stickiness Rate | D22: Derived | E22: DAU / MAU | F22: dau, mau | G22: =IFERROR(XLOOKUP("dau",Input_Fields!$B:$B,Input_Fields!$F:$F,"")/XLOOKUP("mau",Input_Fields!$B:$B,Input_Fields!$F:$F,""),"")
A23: Retention | B23: time_to_implement_vs_goal | C23: Time to Implement vs Goal | D23: Derived | E23: Actual Implementation Days / Expected Implementation Days | F23: actual_implementation_days, expected_implementation_days | G23: =IFERROR(XLOOKUP("actual_implementation_days",Input_Fields!$B:$B,Input_Fields!$F:$F,"")/XLOOKUP("expected_implementation_days",Input_Fields!$B:$B,Input_Fields!$F:$F,""),"")
A24: Retention | B24: nps | C24: NPS | D24: Derived | E24: Promoter % - Detractor % | F24: promoter_pct, detractor_pct | G24: =IFERROR(XLOOKUP("promoter_pct",Input_Fields!$B:$B,Input_Fields!$F:$F,"")-XLOOKUP("detractor_pct",Input_Fields!$B:$B,Input_Fields!$F:$F,""),"")
A25: Retention | B25: csat | C25: CSAT | D25: Derived | E25: Satisfied Responses / Total Responses | F25: satisfied_responses, total_responses | G25: =IFERROR(XLOOKUP("satisfied_responses",Input_Fields!$B:$B,Input_Fields!$F:$F,"")/XLOOKUP("total_responses",Input_Fields!$B:$B,Input_Fields!$F:$F,""),"")
A26: Efficiency & Economics | B26: gross_margin | C26: Gross Margin | D26: Derived | E26: Gross Profit / Total Revenue | F26: gross_profit, total_revenue | G26: =IFERROR(XLOOKUP("gross_profit",Input_Fields!$B:$B,Input_Fields!$F:$F,"")/XLOOKUP("total_revenue",Input_Fields!$B:$B,Input_Fields!$F:$F,""),"")
A27: Efficiency & Economics | B27: subscription_gm | C27: Subscription Gross Margin | D27: Derived | E27: Subscription Gross Profit / Subscription Revenue | F27: subscription_gross_profit, subscription_revenue | G27: =IFERROR(XLOOKUP("subscription_gross_profit",Input_Fields!$B:$B,Input_Fields!$F:$F,"")/XLOOKUP("subscription_revenue",Input_Fields!$B:$B,Input_Fields!$F:$F,""),"")
A28: Efficiency & Economics | B28: services_gm | C28: Services Gross Margin | D28: Derived | E28: Services Gross Profit / Services Revenue | F28: services_gross_profit, services_revenue | G28: =IFERROR(XLOOKUP("services_gross_profit",Input_Fields!$B:$B,Input_Fields!$F:$F,"")/XLOOKUP("services_revenue",Input_Fields!$B:$B,Input_Fields!$F:$F,""),"")
A29: Efficiency & Economics | B29: net_magic_number | C29: Net Magic Number | D29: Derived | E29: Current Quarter Net New ARR / Prior Quarter S&M OpEx | F29: new_logo_arr, expansion_arr, downsell_arr, logo_churn_arr, prior_qtr_sm_opex | G29: =IFERROR(G4/XLOOKUP("prior_qtr_sm_opex",Input_Fields!$B:$B,Input_Fields!$F:$F,""),"")
A30: Efficiency & Economics | B30: gross_magic_number | C30: Gross Magic Number | D30: Derived | E30: Current Quarter Gross New ARR / Prior Quarter S&M OpEx | F30: new_logo_arr, expansion_arr, prior_qtr_sm_opex | G30: =IFERROR(G2/XLOOKUP("prior_qtr_sm_opex",Input_Fields!$B:$B,Input_Fields!$F:$F,""),"")
A31: Efficiency & Economics | B31: simple_cac | C31: Simple CAC | D31: Derived | E31: S&M OpEx / Gross New Logo Customers | F31: sm_opex, gross_new_logo_customers | G31: =IFERROR(XLOOKUP("sm_opex",Input_Fields!$B:$B,Input_Fields!$F:$F,"")/XLOOKUP("gross_new_logo_customers",Input_Fields!$B:$B,Input_Fields!$F:$F,""),"")
A32: Efficiency & Economics | B32: time_adjusted_cac | C32: Time-Adjusted CAC | D32: Derived | E32: Prior Quarter S&M OpEx / Gross New Logo Customers This Quarter | F32: prior_qtr_sm_opex, gross_new_logo_customers | G32: =IFERROR(XLOOKUP("prior_qtr_sm_opex",Input_Fields!$B:$B,Input_Fields!$F:$F,"")/XLOOKUP("gross_new_logo_customers",Input_Fields!$B:$B,Input_Fields!$F:$F,""),"")
A33: Efficiency & Economics | B33: simple_ltv | C33: Simple LTV | D33: Derived | E33: (ARR per Customer * Gross Margin) / Logo Churn Rate | F33: avg_arr_per_customer, gross_margin or gross_margin_pct, logo_churn or provided logo_churn_rate | G33: =IFERROR((XLOOKUP("avg_arr_per_customer",Input_Fields!$B:$B,Input_Fields!$F:$F,"")*IF(XLOOKUP("gross_margin_pct",Input_Fields!$B:$B,Input_Fields!$F:$F,"")="",G26,XLOOKUP("gross_margin_pct",Input_Fields!$B:$B,Input_Fields!$F:$F,"")))/IF(XLOOKUP("logo_churn_rate",Input_Fields!$B:$B,Input_Fields!$F:$F,"")="",G18,XLOOKUP("logo_churn_rate",Input_Fields!$B:$B,Input_Fields!$F:$F,"")),"")
A34: Efficiency & Economics | B34: ltv_cac | C34: LTV / CAC | D34: Derived | E34: Customer LTV / Customer Acquisition Cost | F34: avg_arr_per_customer, margin, churn, sm_opex, gross_new_logo_customers | G34: =IFERROR(G33/G31,"")
A35: Efficiency & Economics | B35: payback_period | C35: Payback Period | D35: Derived | E35: CAC / (ARR per Customer * Gross Margin) | F35: avg_arr_per_customer, margin, sm_opex, gross_new_logo_customers | G35: =IFERROR(G31/(XLOOKUP("avg_arr_per_customer",Input_Fields!$B:$B,Input_Fields!$F:$F,"")*IF(XLOOKUP("gross_margin_pct",Input_Fields!$B:$B,Input_Fields!$F:$F,"")="",G26,XLOOKUP("gross_margin_pct",Input_Fields!$B:$B,Input_Fields!$F:$F,""))),"")
A36: Team & Productivity | B36: sm_opex_per_fte | C36: S&M OpEx per S&M FTE | D36: Derived | E36: (Quarter S&M OpEx * 4) / Average S&M FTEs | F36: sm_opex, avg_sm_ftes | G36: =IFERROR((XLOOKUP("sm_opex",Input_Fields!$B:$B,Input_Fields!$F:$F,"")*4)/XLOOKUP("avg_sm_ftes",Input_Fields!$B:$B,Input_Fields!$F:$F,""),"")
A37: Team & Productivity | B37: ae_per_csm | C37: AE per CSM | D37: Derived | E37: Quota-Carrying AEs / CSMs | F37: qcr_count, csm_count | G37: =IFERROR(XLOOKUP("qcr_count",Input_Fields!$B:$B,Input_Fields!$F:$F,"")/XLOOKUP("csm_count",Input_Fields!$B:$B,Input_Fields!$F:$F,""),"")
A38: Team & Productivity | B38: ae_per_manager | C38: AE per Sales Manager | D38: Derived | E38: Quota-Carrying AEs / Sales Managers | F38: qcr_count, sales_manager_count | G38: =IFERROR(XLOOKUP("qcr_count",Input_Fields!$B:$B,Input_Fields!$F:$F,"")/XLOOKUP("sales_manager_count",Input_Fields!$B:$B,Input_Fields!$F:$F,""),"")
A39: Team & Productivity | B39: ae_per_sdr | C39: AE per SDR | D39: Derived | E39: Quota-Carrying AEs / SDRs | F39: qcr_count, sdr_count | G39: =IFERROR(XLOOKUP("qcr_count",Input_Fields!$B:$B,Input_Fields!$F:$F,"")/XLOOKUP("sdr_count",Input_Fields!$B:$B,Input_Fields!$F:$F,""),"")
A40: Team & Productivity | B40: employee_attrition | C40: Employee Attrition | D40: Derived | E40: QCRs Departed / Average QCRs in Period | F40: qcr_departed, qcr_count | G40: =IFERROR(XLOOKUP("qcr_departed",Input_Fields!$B:$B,Input_Fields!$F:$F,"")/XLOOKUP("qcr_count",Input_Fields!$B:$B,Input_Fields!$F:$F,""),"")
...

Sheet Diagnostic_Output
A1: GTM Diagnostic Output
A2: Auto-calculated from Input_Fields. Populate the User Value column in Input_Fields to populate this summary.
A4: Key Metrics | E4: Data Quality
A5: Metric | B5: Value | C5: Family | E5: Missing Required Inputs
A6: Gross New ARR | B6: =XLOOKUP("gross_new_arr",Metric_Calcs!$B:$B,Metric_Calcs!$G:$G,"") | C6: Growth Drivers | E6: =TEXTJOIN(CHAR(10),TRUE,FILTER(Input_Fields!$C$2:$C$999,(Input_Fields!$E$2:$E$999<>"Optional")*(Input_Fields!$E$2:$E$999<>"Optional / shortcut")*(Input_Fields!$E$2:$E$999<>"Optional / validation")*(Input_Fields!$F$2:$F$999=0),"— All required inputs populated"))
A7: Net New ARR | B7: =XLOOKUP("net_new_arr",Metric_Calcs!$B:$B,Metric_Calcs!$G:$G,"") | C7: Growth Drivers
A8: Ending ARR (Calculated) | B8: =XLOOKUP("ending_arr_calc",Metric_Calcs!$B:$B,Metric_Calcs!$G:$G,"") | C8: Growth Drivers
A9: Pipeline Coverage | B9: =XLOOKUP("pipeline_coverage",Metric_Calcs!$B:$B,Metric_Calcs!$G:$G,"") | C9: Sales Funnel
A10: Weighted Pipeline Coverage | B10: =XLOOKUP("weighted_pipeline_coverage",Metric_Calcs!$B:$B,Metric_Calcs!$G:$G,"") | C10: Sales Funnel
A11: Win Rate | B11: =XLOOKUP("win_rate",Metric_Calcs!$B:$B,Metric_Calcs!$G:$G,"") | C11: Sales Funnel
A12: Quarterly Annualized NDR | B12: =XLOOKUP("quarterly_ndr",Metric_Calcs!$B:$B,Metric_Calcs!$G:$G,"") | C12: Retention
A13: Quarterly Annualized GDR | B13: =XLOOKUP("quarterly_gdr",Metric_Calcs!$B:$B,Metric_Calcs!$G:$G,"") | C13: Retention
A14: Logo Retention | B14: =XLOOKUP("logo_retention",Metric_Calcs!$B:$B,Metric_Calcs!$G:$G,"") | C14: Retention
A15: Gross Margin | B15: =XLOOKUP("gross_margin",Metric_Calcs!$B:$B,Metric_Calcs!$G:$G,"") | C15: Efficiency & Economics
A16: Net Magic Number | B16: =XLOOKUP("net_magic_number",Metric_Calcs!$B:$B,Metric_Calcs!$G:$G,"") | C16: Efficiency & Economics
A17: Simple CAC | B17: =XLOOKUP("simple_cac",Metric_Calcs!$B:$B,Metric_Calcs!$G:$G,"") | C17: Efficiency & Economics
A18: Simple LTV | B18: =XLOOKUP("simple_ltv",Metric_Calcs!$B:$B,Metric_Calcs!$G:$G,"") | C18: Efficiency & Economics
A19: LTV / CAC | B19: =XLOOKUP("ltv_cac",Metric_Calcs!$B:$B,Metric_Calcs!$G:$G,"") | C19: Efficiency & Economics
A20: S&M OpEx per FTE | B20: =XLOOKUP("sm_opex_per_fte",Metric_Calcs!$B:$B,Metric_Calcs!$G:$G,"") | C20: Team & Productivity
A21: NNARR per S&M FTE | B21: =XLOOKUP("nnarr_per_sm_fte",Metric_Calcs!$B:$B,Metric_Calcs!$G:$G,"") | C21: Team & Productivity
A22: Sales Capacity | B22: =XLOOKUP("sales_capacity",Metric_Calcs!$B:$B,Metric_Calcs!$G:$G,"") | C22: Team & Productivity
A23: Rep Attainment | B23: =XLOOKUP("rep_attainment",Metric_Calcs!$B:$B,Metric_Calcs!$G:$G,"") | C23: Team & Productivity
A24: Ramp Rate | B24: =XLOOKUP("ramp_rate",Metric_Calcs!$B:$B,Metric_Calcs!$G:$G,"") | C24: Team & Productivity
A25: Ending ARR Attainment | B25: =XLOOKUP("ending_arr_attainment",Metric_Calcs!$B:$B,Metric_Calcs!$G:$G,"") | C25: Fiscal Maturity
