Workbook

Sheet COVER
B2: Shopify, Inc. (SHOP) | Deal Intelligence Workbook
B3: NYSE: SHOP | Public Equity Long | Entry: ~$108/share | PT: $150 | May 2026
B5: Workbook Navigation
B6: Tab | C6: Purpose | D6: Key Inputs
B7: INPUTS | C7: Deal assumptions, entry/exit, thesis, NTB names | D7: Shopify entry at $108/share; 3-yr hold to FY2028
B8: FINANCIALS | C8: Historical P&L — FY2022–FY2025A (adj. non-GAAP) | D8: Pre-populated; edit to override
B9: FINANCIAL MODEL | C9: Operating model — FY2022A + FY2026–2030E projections | D9: Yellow projection assumption cells
B10: DRIVER TREE | C10: Thesis decomposition — GMV, Payments, AI, Enterprise | D10: Base/Upside EV per driver; NTB linkage
B11: NTB REGISTRY | C11: 6 Shopify NTBs — evidence, MOIC impact, gaps | D11: Evidence status; MOIC impact ($M)
B12: KPI TREE | C12: Shopify KPI hierarchy mapped to financial model | D12: Budget (consensus) vs. actual (Q1'26A)
B13: MOIC BRIDGE | C13: MOIC waterfall — entry equity to exit by NTB | D13: Pulls from NTB Registry & INPUTS
B15: Investment Summary
B16: Metric | C16: Value | D16: Source
B17: Share Price (Entry) | C17: $108 | D17: Post-Q1'26 earnings — May 6, 2026
B18: Enterprise Value | C18: ~$135B | D18: Mkt cap ~$141B less net cash ~$5.7B
B19: Q1'26 Revenue | C19: $3,170M | D19: Shopify Q1'26 earnings release
B20: Q1'26 GMV | C20: $100.7B | D20: +35% YoY; first $100B+ quarter
B21: Q1'26 FCF Margin | C21: 15.0% | D21: $476M FCF on $3,170M revenue
B22: FY2026E Revenue | C22: $14,885M | D22: Street consensus: GS, JPM, Baird, Citizens, KeyBanc
B23: FY2026E EBITDA Mgn | C23: ~18.7% | D23: Consensus range: 18.3%–19.1%
B24: 12-mo Price Target | C24: $150 | D24: +39% upside; memo thesis
B25: 3-yr Base MOIC | C25: ~1.50x | D25: 38x–45x FY2028E EBITDA of ~$4.5B
B26: Conviction Level | C26: HIGH | D26: See NTB Registry for gating items
B28: Color Coding
B29: Color | C29: Meaning | D29: Action
B30: BLUE text / YELLOW bg | C30: BLUE text / YELLOW bg | D30: Hardcoded input — override for scenario analysis
B31: BLACK text | C31: BLACK text | D31: Formula — do not overwrite
B32: GREEN text | C32: GREEN text | D32: Cross-sheet link — do not overwrite
B33: Green background | C33: Green background | D33: Confirmed / PASS evidence status
B34: Orange background | C34: Orange background | D34: Partial — needs more evidence
B35: Red background | C35: Red background | D35: Gap / CRITICAL — NTB not yet supported

Sheet INPUTS
B2: Deal Inputs — Shopify, Inc. (SHOP)
B4: Company & Deal
B5: Field | C5: Value
B6: Company Name | C6: Shopify, Inc. (SHOP)
B7: Deal Type | C7: Public Equity Long
B8: Sector | C8: Technology / eCommerce Infrastructure
B9: Investment Thesis (one sentence) | C9: Dominant commerce OS processing $100B+ qtrly GMV; Payments take-rate compounding 40%+ YoY; AI-native architecture positions SHOP as agentic-commerce infrastructure layer; post-Q1 selloff creates entry at 9.1x FY26E EV/Revenue.
B10: Entry Year | C10: 2026
B11: Exit Year (projected) | C11: 2028
B13: Entry Assumptions (at $108/share — May 2026)
B14: Metric ($M unless noted) | C14: Value
B15: Entry Revenue ($M) [FY2026E consensus] | C15: 14885
B16: Entry EBITDA ($M) [FY2026E, 18.7% adj.] | C16: 2785
B17: Entry EBITDA Margin | C17: 0.187
B18: Entry EV/EBITDA Multiple [NTM FY2026E] | C18: 48.5
B19: Entry EV ($M) [=EBITDA × Multiple] | C19: =C16*C18
B20: Net Debt at Entry ($M) [net cash = neg] | C20: -5700
B21: Equity Invested ($M) [=EV − Net Debt] | C21: =C19-C20
B23: Exit Assumptions (FY2028E Base Case)
B24: Metric | C24: Value
B25: Exit Revenue ($M) [FY2028E, ~22% YoY] | C25: 22450
B26: Exit EBITDA ($M) [FY2028E, ~20% margin] | C26: 4490
B27: Exit EV/EBITDA Multiple | C27: 45
B28: Exit EV ($M) [=EBITDA × Multiple] | C28: 202050
B29: Net Debt at Exit ($M) [growing net cash] | C29: -8500
B30: Proceeds to Equity ($M) [=Exit EV − Net Debt] | C30: 210550
B32: Returns Summary
B33: Metric | C33: Value
B34: Gross MOIC | C34: =IFERROR(C30/C21,"-")
B35: Holding Period (Years) | C35: =IFERROR(C11-C10,"-")
B36: Implied IRR (approx) | C36: =IFERROR(POWER(C30/C21,1/(C11-C10))-1,"-")
B38: NTB Registry — Need-to-Believe Statements
B39: Shopify has 6 NTBs. Statements below link to NTB Registry & Driver Tree tabs.
B40: NTB # | C40: NTB Statement
B41: NTB 1 | C41: NTB-1: GMV growth sustains 25%+ through FY2027 despite tougher comps & FX normalisation [H / LOW / CRITICAL]
B42: NTB 2 | C42: NTB-2: Shopify Payments GPV penetration reaches 70%+ within 24 months; take-rate expands to 2.50%+ of GMV [H / MEDIUM / CRITICAL]
B43: NTB 3 | C43: NTB-3: AI-driven commerce (Sidekick, UCP, agentic checkout) is net revenue-positive; LLM cost inflation contained [H / LOW / CRITICAL]
B44: NTB 4 | C44: NTB-4: Enterprise wins (Shopify Plus) are durable and do not erode margins via bespoke development [E / MEDIUM / NON-CRITICAL]
B45: NTB 5 | C45: NTB-5: FCF margin expands from 15-17% to 20%+ by FY2028 without sacrificing 25%+ revenue growth [E / MEDIUM / PARTIAL]
B46: NTB 6 | C46: NTB-6: Consumer/macro does not materially deteriorate in FY2026-27, sustaining SMB GMV compounding [H / LOW / CRITICAL]
...

Sheet FINANCIALS
B2: Historical Financials — Shopify FY2022–FY2025A (Adj. Non-GAAP, $M)
B4: Adj. non-GAAP figures. Revenue/GP/EBITDA from earnings releases. OpEx split approximate. Sources: Shopify Q1'26 earnings; GS, JPM, Citizens, Baird, KeyBanc research (May 2026).
B6: Line Item ($M) | C6: FY2022 | D6: FY2023 | E6: FY2024 | F6: FY2025A | G6: Notes / Source
B7: INCOME STATEMENT
B8: Revenue ($M) | C8: 5595 | D8: 7061 | E8: 8884 | F8: 11556 | G8: Shopify Q1/Q4'26 earnings releases; FY2025A +30.2% YoY
B9: YoY Growth % | D9: 0.262 | E9: 0.258 | F9: 0.302 | G9: Calculated YoY
B10: Cost of Revenue ($M) | C10: 2862 | D10: 3604 | E10: 4504 | F10: 5800 | G10: Blended: Sub ~20% COGS, MS ~62% COGS
B11: Gross Profit ($M) | C11: 2733 | D11: 3457 | E11: 4380 | F11: 5756 | G11: Blended GM: 48.8% (FY22) → 49.8% (FY25)
B12: Gross Margin % | C12: 0.488 | D12: 0.49 | E12: 0.493 | F12: 0.498
B13: Sales & Marketing ($M) | C13: 895 | D13: 888 | E13: 1043 | F13: 1422 | G13: Non-GAAP (excl. SBC)
B14: Research & Development ($M) | C14: 810 | D14: 729 | E14: 1155 | F14: 1244 | G14: Reduced post-2022 workforce restructuring
B15: General & Administrative ($M) | C15: 806 | D15: 840 | E15: 599 | F15: 1080 | G15: Non-GAAP
B16: Total Operating Expenses ($M) | C16: 2511 | D16: 2457 | E16: 2797 | F16: 3746 | G16: Sum S&M + R&D + G&A (non-GAAP)
B17: EBITDA (adj.) ($M) | C17: 222 | D17: 1000 | E17: 1583 | F17: 2010 | G17: Non-GAAP adj. EBITDA; source: earnings releases + GS/JPM
B18: EBITDA Margin % | C18: 0.04 | D18: 0.142 | E18: 0.178 | F18: 0.174
B19: D&A ($M) | C19: 200 | D19: 235 | E19: 265 | F19: 310 | G19: Approximate; ~3.6% → 2.7% of revenue
B20: EBIT ($M) | C20: 22 | D20: 765 | E20: 1318 | F20: 1700 | G20: EBITDA minus D&A
B21: Interest Income/(Expense) ($M) | C21: -85 | D21: -195 | E21: -232 | F21: -295 | G21: Net interest income (Shopify has net cash position)
B22: EBT ($M) | C22: 107 | D22: 960 | E22: 1550 | F22: 1995
B23: Tax ($M) | C23: 16 | D23: 144 | E23: 233 | F23: 299 | G23: Effective rate ~15% on adj. basis
B24: Net Income (adj.) ($M) | C24: 91 | D24: 816 | E24: 1317 | F24: 1696 | G24: Adj. net income (non-GAAP)
B26: BALANCE SHEET (KEY ITEMS)
B27: Cash & Equivalents ($M) | C27: 5000 | D27: 5500 | E27: 6200 | F27: 7900 | G27: Q4 balance; FY2025 cash per Q1'26 BS
B28: Total Debt ($M) | C28: 921 | D28: 921 | E28: 921 | F28: 921 | G28: $921M notes; no revolving credit drawn
B29: Net Debt ($M) [neg = net cash] | C29: -4079 | D29: -4579 | E29: -5279 | F29: -6979 | G29: Negative = net cash
B30: Total Assets ($M) | C30: 9500 | D30: 10900 | E30: 12800 | F30: 16200 | G30: Total assets per annual 10-K
B32: CASH FLOW (KEY ITEMS)
B33: Operating Cash Flow ($M) | C33: 378 | D33: 1035 | E33: 1690 | F33: 2207 | G33: OCF = FCF + Capex
B34: Capex ($M) | C34: 100 | D34: 130 | E34: 160 | F34: 200 | G34: ~1.8% of revenue; primarily technology infrastructure
B35: Free Cash Flow ($M) | C35: 278 | D35: 905 | E35: 1530 | F35: 2007 | G35: FCF = OCF - Capex; FY2025A $2,007M (17.4% margin) per Q1'26 release

Sheet FINANCIAL MODEL
B2: Financial Model — Shopify Historical & Projections
B4: Line Item ($M) | C4: FY2022 | D4: FY2023 | E4: FY2024 | F4: FY2025A | G4: FY2026E | H4: FY2027E | I4: FY2028E | J4: FY2029E | K4: FY2030E | L4: Notes
B5: Projection Assumptions (Yellow = change for scenario analysis)
B6: FY2026E–FY2030E assumptions driven by consensus estimates + IC memo thesis.
B7: Revenue Growth % | G7: 0.29 | H7: 0.24 | I7: 0.22 | J7: 0.2 | K7: 0.18 | L7: FY2026E: +29% (consensus); decel to +18% by FY2030E
B8: Gross Margin % | G8: 0.5 | H8: 0.505 | I8: 0.51 | J8: 0.515 | K8: 0.52 | L8: 50.0%–52.0%; modest Sub mix uplift
B9: S&M % of Revenue | G9: 0.125 | H9: 0.12 | I9: 0.118 | J9: 0.115 | K9: 0.112 | L9: 12.5% → 11.2%; OpEx leverage on scale
B10: R&D % of Revenue | G10: 0.113 | H10: 0.115 | I10: 0.115 | J10: 0.113 | K10: 0.11 | L10: 11.3% → 11.0%; AI capex partially capitalised
B11: G&A % of Revenue | G11: 0.075 | H11: 0.076 | I11: 0.077 | J11: 0.075 | K11: 0.073 | L11: 7.5% → 7.3%; fixed overhead scale benefit
B12: D&A % of Revenue | G12: 0.028 | H12: 0.027 | I12: 0.026 | J12: 0.025 | K12: 0.024 | L12: 2.8% → 2.4%; intangible amortisation declining
B13: Tax Rate % | G13: 0.15 | H13: 0.15 | I13: 0.15 | J13: 0.15 | K13: 0.15 | L13: 15% effective; SBC deductions + R&D credits
B14: Capex % of Revenue | G14: 0.017 | H14: 0.016 | I14: 0.015 | J14: 0.015 | K14: 0.014 | L14: 1.7% → 1.4%; lean capex model
B16: Income Statement
B17: Revenue | C17: 5595 | D17: 7061 | E17: 8884 | F17: 11556 | G17: =F17*(1+G7) | H17: =G17*(1+H7) | I17: =H17*(1+I7) | J17: =I17*(1+J7) | K17: =J17*(1+K7) | L17: Q1'26A $3,170M (+34% YoY); FY2026E consensus $14,885M (+29%)
B18: YoY Growth % | D18: 0.262 | E18: 0.258 | F18: 0.302 | G18: =IFERROR(G17/F17-1,"-") | H18: =IFERROR(H17/G17-1,"-") | I18: =IFERROR(I17/H17-1,"-") | J18: =IFERROR(J17/I17-1,"-") | K18: =IFERROR(K17/J17-1,"-")
B19: Gross Profit | C19: 2733 | D19: 3457 | E19: 4380 | F19: 5756 | G19: =G17*G8 | H19: =H17*H8 | I19: =I17*I8 | J19: =J17*J8 | K19: =K17*K8 | L19: Sub Solutions ~80% GM; Merchant Solutions ~38% GM; blended expands
B20: Gross Margin % | C20: 0.488 | D20: 0.49 | E20: 0.493 | F20: 0.498 | G20: =IFERROR(G19/G17,"-") | H20: =IFERROR(H19/H17,"-") | I20: =IFERROR(I19/I17,"-") | J20: =IFERROR(J19/J17,"-") | K20: =IFERROR(K19/K17,"-")
B21: Sales & Marketing | C21: 895 | D21: 888 | E21: 1043 | F21: 1422 | G21: =G17*G9 | H21: =H17*H9 | I21: =I17*I9 | J21: =J17*J9 | K21: =K17*K9
B22: Research & Development | C22: 810 | D22: 729 | E22: 1155 | F22: 1244 | G22: =G17*G10 | H22: =H17*H10 | I22: =I17*I10 | J22: =J17*J10 | K22: =K17*K10 | L22: AI/Sidekick investment headwind ~FY2026–27
B23: General & Administrative | C23: 806 | D23: 840 | E23: 599 | F23: 1080 | G23: =G17*G11 | H23: =H17*H11 | I23: =I17*I11 | J23: =J17*J11 | K23: =K17*K11
B24: Total OpEx | C24: 2511 | D24: 2457 | E24: 2797 | F24: 3746 | G24: =G21+G22+G23 | H24: =H21+H22+H23 | I24: =I21+I22+I23 | J24: =J21+J22+J23 | K24: =K21+K22+K23 | L24: Q1'26 OpEx/Rev = 32%; target 28% by FY2030E via operating leverage
B25: EBITDA (adj.) | C25: 222 | D25: 1000 | E25: 1583 | F25: 2010 | G25: =G19-G24 | H25: =H19-H24 | I25: =I19-I24 | J25: =J19-J24 | K25: =K19-K24 | L25: FY2025A 17.4%; FY2026E ~18.7% consensus; FY2028E base ~20%
B26: EBITDA Margin % | C26: 0.04 | D26: 0.142 | E26: 0.178 | F26: 0.174 | G26: =IFERROR(G25/G17,"-") | H26: =IFERROR(H25/H17,"-") | I26: =IFERROR(I25/I17,"-") | J26: =IFERROR(J25/J17,"-") | K26: =IFERROR(K25/K17,"-")
B27: D&A | C27: 200 | D27: 235 | E27: 265 | F27: 310 | G27: =G17*G12 | H27: =H17*H12 | I27: =I17*I12 | J27: =J17*J12 | K27: =K17*K12
B28: EBIT | C28: 22 | D28: 765 | E28: 1318 | F28: 1700 | G28: =G25-G27 | H28: =H25-H27 | I28: =I25-I27 | J28: =J25-J27 | K28: =K25-K27
B29: Interest Income/(Expense) | C29: -85 | D29: -195 | E29: -232 | F29: -295 | L29: Shopify earns net interest on ~$6-9B cash; model as income (negative expense)
B30: EBT | C30: 107 | D30: 960 | E30: 1550 | F30: 1995 | G30: =G28-G29 | H30: =H28-H29 | I30: =I28-I29 | J30: =J28-J29 | K30: =K28-K29
B31: Tax | C31: 16 | D31: 144 | E31: 233 | F31: 299 | G31: =G30*G13 | H31: =H30*H13 | I31: =I30*I13 | J31: =J30*J13 | K31: =K30*K13 | L31: ~15% effective adj. rate; SBC deductions support
B32: Net Income (adj.) | C32: 91 | D32: 816 | E32: 1317 | F32: 1696 | G32: =G30-G31 | H32: =H30-H31 | I32: =I30-I31 | J32: =J30-J31 | K32: =K30-K31
B34: Free Cash Flow
B35: EBITDA (adj.) | G35: =G25 | H35: =H25 | I35: =I25 | J35: =J25 | K35: =K25
B36: Less: Capex | C36: 100 | D36: 130 | E36: 160 | F36: 200 | G36: =G17*G14 | H36: =H17*H14 | I36: =I17*I14 | J36: =J17*J14 | K36: =K17*K14 | L36: ~1.7%→1.4% of rev; technology infrastructure + office
B37: Less: Interest & Other | L37: Leave blank; interest income captured in NI above
B38: Free Cash Flow | C38: 278 | D38: 905 | E38: 1530 | F38: 2007 | G38: =G25-G36-G37 | H38: =H25-H36-H37 | I38: =I25-I36-I37 | J38: =J25-J36-J37 | K38: =K25-K36-K37 | L38: FY2025A $2,007M (17.4%); FY2026E ~$2,610M cons (17.5%); FY2028E ~$4.1B target
B40: Shopify-Specific KPIs (Supplemental)
B41: GMV ($B) | C41: 197 | D41: 236 | E41: 282 | F41: 329 | G41: 489 | H41: 597 | I41: 726 | J41: 871 | K41: 1027 | L41: Q1'26A: $100.7B (+35%); FY2025A ~$329B (+23%)
B42: GPV Penetration % of GMV | E42: 0.6 | F42: 0.64 | G42: 0.67 | H42: 0.7 | I42: 0.72 | J42: 0.73 | K42: 0.74 | L42: Q1'26A: 67%; targeting 72%+ by FY2028
B43: Merchant Solutions Rev/GMV (Take Rate) | E43: 0.022 | F43: 0.023 | G43: 0.024 | H43: 0.024 | I43: 0.0245 | J43: 0.025 | K43: 0.025 | L43: Q1'26A: 2.40% (+7bps YoY)
B44: MRR ($M) | E44: 182 | F44: 200 | G44: 212 | H44: 248 | I44: 291 | J44: 340 | K44: 397 | L44: Q1'26A: $212M (+16% YoY); Plus ~28% of MRR

Sheet DRIVER TREE
B2: Driver Tree — Shopify Thesis Decomposition to MOIC
B4: MECE thesis decomposition. Base = EV contribution in base case. Upside = bull-case EV. MOIC Delta = (Upside - Base) / Entry Equity ($140.7B). Source: IC memo driver tree analysis (May 2026).
B6: Lvl | C6: Value Driver | D6: Type | E6: NTB | F6: Evidence Tier | G6: Base ($M) | H6: Upside ($M) | I6: MOIC Delta | J6: Notes
B7: 1 | C7: GMV / Revenue Growth | D7: Revenue | I7: =IFERROR(SUM(I8:I10),"-") | J7: Composite of 3 parallel expansion vectors
B8: 2 | C8: Same-Cohort GMV Expansion (B1a) | D8: Revenue | E8: NTB 1 | F8: T1 | G8: 25000 | H8: 35000 | I8: =IFERROR((H8-G8)/INPUTS!C21,"-") | J8: JPM cohort data; 10yr track record; T1 evidence
B9: 2 | C9: New Merchant Acquisition (A1) | D9: Revenue | E9: NTB 1 | F9: T1 | G9: 15000 | H9: 22000 | I9: =IFERROR((H9-G9)/INPUTS!C21,"-") | J9: Intl. optionality; pull-forward normalisation complete
B10: 2 | C10: Geographic Expansion ex-NA (B1e) | D10: Revenue | E10: NTB 1 | F10: T2 | G10: 8000 | H10: 14000 | I10: =IFERROR((H10-G10)/INPUTS!C21,"-") | J10: Europe +48% YoY; <5yr track record in most markets
B11: 1 | C11: Payments Monetization | D11: Revenue | I11: =IFERROR(SUM(I12:I14),"-") | J11: Variance-dominant node in thesis (B2a × B2b)
B12: 2 | C12: GPV Penetration 67%→72%+ (B2a) | D12: Revenue | E12: NTB 2 | F12: T1 | G12: 12000 | H12: 20000 | I12: =IFERROR((H12-G12)/INPUTS!C21,"-") | J12: T1 evidence; 12yr track; base-rate divergence noted
B13: 2 | C13: Payments Take Rate 2.40%→2.45% (B2b) | D13: Revenue | E13: NTB 2 | F13: T1 | G13: 6000 | H13: 10000 | I13: =IFERROR((H13-G13)/INPUTS!C21,"-") | J13: Contested directionally; Stripe/Adyen competitive bids
B14: 2 | C14: Shopify Capital / MCA (B2c) | D14: Revenue | E14: NTB 2 | F14: T2 | G14: 2000 | H14: 5000 | I14: =IFERROR((H14-G14)/INPUTS!C21,"-") | J14: Temp T3 until Q3'26 clean comp post-reclassification
B15: 1 | C15: Margin & FCF Expansion | D15: Cost | I15: =IFERROR(SUM(I16:I18),"-") | J15: OpEx leverage: 32% → 28% of revenue by FY2030E
B16: 2 | C16: OpEx Leverage (32%→28% Rev) | D16: Cost | E16: NTB 5 | F16: T1 | G16: 8000 | H16: 14000 | I16: =IFERROR((H16-G16)/INPUTS!C21,"-") | J16: Q1'24=41%, Q1'25=36%, Q1'26=32%; trend well-evidenced
B17: 2 | C17: Sub Solutions Gross Margin ~80% | D17: Cost | E17: NTB 5 | F17: T2 | G17: 3000 | H17: 7000 | I17: =IFERROR((H17-G17)/INPUTS!C21,"-") | J17: Stable; AI/LLM cost headwind vs scale benefit
B18: 1 | C18: AI / Platform Optionality | D18: Multiple | I18: =IFERROR(SUM(I19:I21),"-") | J18: T4 drivers — binary; cannot be load-bearing in base case
B19: 2 | C19: Sidekick / Agentic Commerce (C1) | D19: Multiple | E19: NTB 3 | F19: T4 | G19: 0 | H19: 15000 | I19: =IFERROR((H19-G19)/INPUTS!C21,"-") | J19: T4: WAU 4× stated; no controlled retention link
B20: 2 | C20: Universal Checkout Protocol (C3) | D20: Multiple | E20: NTB 3 | F20: T4 | G20: 0 | H20: 25000 | I20: =IFERROR((H20-G20)/INPUTS!C21,"-") | J20: T4: structurally novel; not commercially deployed
B21: 1 | C21: Enterprise Upmarket Migration | D21: Revenue | I21: =IFERROR(SUM(I22:I24),"-") | J21: Plus ~28% of MRR; $25M+ GMV fastest-growing segment
B22: 2 | C22: Shopify Plus MRR Growth (A2) | D22: Revenue | E22: NTB 4 | F22: T2 | G22: 4000 | H22: 8000 | I22: =IFERROR((H22-G22)/INPUTS!C21,"-") | J22: LVMH, Mulberry wins; pipeline opacity limits bounding
B23: 2 | C23: Enterprise GMV Concentration (B1c) | D23: Revenue | E23: NTB 4 | F23: T3 | G23: 2000 | H23: 5000 | I23: =IFERROR((H23-G23)/INPUTS!C21,"-") | J23: T3: not observed through recession; G2/G3 gating
B24: 1 | C24: Multiple & Macro Risk | D24: Multiple | I24: =IFERROR(SUM(I25:I27),"-") | J24: FY2026E at 48.5x NTM EBITDA — re-rating risk is real
B25: 2 | C25: Multiple Re-rating (sustained growth) | D25: Multiple | E25: NTB 1 | F25: T1 | G25: -20000 | H25: 5000 | I25: =IFERROR((H25-G25)/INPUTS!C21,"-") | J25: Base: modest compression; bull: sustained at 45x+ on growth
B26: 2 | C26: Macro / Consumer Softness (B1d) | D26: Multiple | E26: NTB 6 | F26: T1 | G26: -5000 | H26: 2000 | I26: =IFERROR((H26-G26)/INPUTS!C21,"-") | J26: T1 evidence; tariff/PCE risk in H2'26
C28: Total Bull-Case MOIC Delta (Sum of L2 drivers) | I28: =IFERROR(SUM(I7:I27),"-") | J28: Base case MOIC ~1.27x; bull case ~1.84x; 12-mo PT ~1.39x ($150)

Sheet NTB REGISTRY
B2: NTB Registry — Shopify Evidence & MOIC Tracking
B4: Epistemic status: [F]=Fact, [E]=Estimate, [H]=Hypothesis. MOIC impact = incremental equity value vs base if NTB confirmed. NTBs 1, 2, 3, 6 are thesis-critical. Gap = blocks IC distribution.
B6: MOIC Check (NTBs 1-6): | D6: =IFERROR(SUM(F8:F13)/INPUTS!C21,"-") | E6: =IFERROR(IF(SUM(F8:F13)/INPUTS!C21>0.4,"PASS — >40% MOIC accounted","CHECK — review allocations"),"-")
B7: # | C7: NTB Statement (from INPUTS) | D7: Evidence Status | E7: Boundability | F7: MOIC Impact ($M) | G7: MOIC (x) | H7: Primary Risk / Bear Case | I7: Information Gap | J7: Owner | K7: Due
B8: NTB 1 | C8: =INPUTS!C41 | D8: Gap — critical [H] | E8: LOW — single data quarter | F8: 22000 | G8: =IFERROR(F8/INPUTS!C21,"-") | H8: Q2'26 GMV decel to high-20s confirms or disproves; Corr-4 (macro + churn) amplifies | I8: Monitor Q2'26 GMV actuals (Aug 2026); North America same-store GMV trend | J8: IC Team | K8: Q2'26
B9: NTB 2 | C9: =INPUTS!C42 | D9: Partial — needs more [E] | E9: MEDIUM — quarterly disclosed | F9: 18000 | G9: =IFERROR(F9/INPUTS!C21,"-") | H9: Stripe/Adyen offer lower interchange to Plus merchants; opt-out risk via App Store | I9: Track quarterly GPV/GMV ratio; confirm take rate Q-to-Q in 2026 | J9: IC Team | K9: Q2'26
B10: NTB 3 | C10: =INPUTS!C43 | D10: Gap — critical [H] | E10: LOW — anecdotal only | F10: 8000 | G10: =IFERROR(F10/INPUTS!C21,"-") | H10: LLM costs growing; Subscription gross margin -10bps YoY. Sidekick = cost centre currently | I10: Monitor Subscription gross margin trajectory; Sidekick monetisation path; UCP merchant adoption | J10: IC Team | K10: Q2'26
B11: NTB 4 | C11: =INPUTS!C44 | D11: Partial — needs more [E] | E11: MEDIUM | F11: 6000 | G11: =IFERROR(F11/INPUTS!C21,"-") | H11: Bespoke integration costs may grow with enterprise complexity; SAP/Hybris still stronger for complex ERP | I11: Plus churn analysis (not public); track Plus as % of MRR quarterly | J11: IC Team | K11: Q2'26
B12: NTB 5 | C12: =INPUTS!C45 | D12: Partial — needs more [E] | E12: MEDIUM — trend-based | F12: 10000 | G12: =IFERROR(F12/INPUTS!C21,"-") | H12: MCA reclassification creates 200-300bps FCF drag in Q2'26; AI/Sidekick is near-term headwind | I12: FCF margin <17% for 2+ qtrs = bearish signal; Q2'26 FCF guide: mid-teens | J12: IC Team | K12: Q2'26
B13: NTB 6 | C13: =INPUTS!C46 | D13: Gap — critical [H] | E13: LOW — limited recession history | F13: 5000 | G13: =IFERROR(F13/INPUTS!C21,"-") | H13: SMB cohort vulnerable to tariff-driven AOV compression; Corr-4 (macro + churn) cascades | I13: Monitor PCE, credit card spending; SHOP GMV limited recession data | J13: IC Team | K13: Q2'26
C15: Total NTB MOIC Impact (if all confirmed) | F15: =SUM(F8:F14) | G15: =IFERROR(F15/INPUTS!C21,"-")

Sheet KPI TREE
B2: KPI Tree — Shopify Management Plan Audit
B4: FY2026E Budget = Street consensus (May 2026). Actual = Q1'26A annualised or FY2025A. Green = on track. Orange = watch. Red = behind plan.
B6: Lvl | C6: KPI Name | D6: Category | E6: Financial Model Line | F6: Frequency | G6: FY2026E Budget | H6: FY2025A Actual | I6: Variance ($) | J6: Variance % | K6: Status | L6: Notes
B7: NS | C7: NORTH STAR — GMV ($B) | D7: Scale | F7: Quarterly | G7: 489 | H7: 329 | I7: =IFERROR(H7-G7,"-") | J7: =IFERROR(I7/G7,"-") | K7: On Track | L7: Q1'26A: $100.7B (+35%); FY2026E: $489B consensus
B8: 1 | C8: Total Revenue ($M) | D8: Growth | F8: Monthly | G8: 14885 | H8: 11556 | I8: =IFERROR(H8-G8,"-") | J8: =IFERROR(I8/G8,"-") | K8: On Track | L8: Q1'26A: $3,170M (+34%); consensus $14.9B
B9: 2 | C9: Subscription Solutions ($M) | D9: Growth | F9: Monthly | G9: 3440 | H9: 2752 | I9: =IFERROR(H9-G9,"-") | J9: =IFERROR(I9/G9,"-") | K9: Watch | L9: Q1'26A: $750M (+21%); 23% of Q1 rev
B10: 2 | C10: Merchant Solutions ($M) | D10: Growth | F10: Monthly | G10: 11445 | H10: 8804 | I10: =IFERROR(H10-G10,"-") | J10: =IFERROR(I10/G10,"-") | K10: On Track | L10: Q1'26A: $2,420M (+39%); 77% of Q1 rev
B11: 2 | C11: MRR ($M) | D11: Growth | F11: Monthly | G11: 248 | H11: 200 | I11: =IFERROR(H11-G11,"-") | J11: =IFERROR(I11/G11,"-") | K11: On Track | L11: Q1'26A: $212M (+16%); Plus ~28%
B12: 1 | C12: Blended Gross Margin | D12: Margin | F12: Monthly | G12: 0.5 | H12: 0.498 | I12: =IFERROR(H12-G12,"-") | J12: =IFERROR(I12/G12,"-") | K12: On Track | L12: Q1'26A: 48.8%; modest improvement expected
B13: 2 | C13: Sub Solutions Gross Margin | D13: Margin | F13: Monthly | G13: 0.8 | H13: 0.8 | I13: =IFERROR(H13-G13,"-") | J13: =IFERROR(I13/G13,"-") | K13: Watch | L13: AI/LLM cost headwind; -10bps YoY in Q1'26
B14: 2 | C14: Merchant Solutions Gross Margin | D14: Margin | F14: Monthly | G14: 0.38 | H14: 0.375 | I14: =IFERROR(H14-G14,"-") | J14: =IFERROR(I14/G14,"-") | K14: On Track | L14: Payments mix increasing; take rate expanding
B15: 1 | C15: Adj. EBITDA Margin | D15: Margin | F15: Monthly | G15: 0.187 | H15: 0.174 | I15: =IFERROR(H15-G15,"-") | J15: =IFERROR(I15/G15,"-") | K15: On Track | L15: Q1'26A: 16.5% (adj.); opex leverage continues
B16: 2 | C16: S&M % of Revenue | D16: Efficiency | F16: Monthly | G16: 0.125 | H16: 0.123 | I16: =IFERROR(H16-G16,"-") | J16: =IFERROR(I16/G16,"-") | K16: On Track | L16: Q1'26A: ~12.1%
B17: 2 | C17: R&D % of Revenue | D17: Efficiency | F17: Monthly | G17: 0.113 | H17: 0.108 | I17: =IFERROR(H17-G17,"-") | J17: =IFERROR(I17/G17,"-") | K17: Watch | L17: AI/Sidekick investment increasing R&D as % rev
B18: 2 | C18: OpEx Total % of Revenue | D18: Efficiency | F18: Monthly | G18: 0.313 | H18: 0.324 | I18: =IFERROR(H18-G18,"-") | J18: =IFERROR(I18/G18,"-") | K18: On Track | L18: Q1'26 = 32%; targeting 31% FY2026E
B19: 1 | C19: GMV Specific KPIs | D19: Growth | F19: Quarterly | I19: =IFERROR(H19-G19,"-") | J19: =IFERROR(I19/G19,"-") | K19: N/A
B20: 2 | C20: GPV Penetration % GMV | D20: Payments | F20: Quarterly | G20: 0.68 | H20: 0.64 | I20: =IFERROR(H20-G20,"-") | J20: =IFERROR(I20/G20,"-") | K20: On Track | L20: Q1'26A: 67%; +200bps/yr trajectory
B21: 2 | C21: Payments Take Rate (GPV/Rev) | D21: Payments | F21: Quarterly | G21: 0.024 | H21: 0.023 | I21: =IFERROR(H21-G21,"-") | J21: =IFERROR(I21/G21,"-") | K21: On Track | L21: Q1'26A: 2.40% (+7bps YoY)
B22: 2 | C22: B2B GMV Growth % | D22: Growth | F22: Quarterly | G22: 0.6 | I22: =IFERROR(H22-G22,"-") | J22: =IFERROR(I22/G22,"-") | K22: Watch | L22: Q1'26A: +80% YoY; early-stage, pre-scale
B23: 2 | C23: International GMV Growth % | D23: Growth | F23: Quarterly | G23: 0.35 | I23: =IFERROR(H23-G23,"-") | J23: =IFERROR(I23/G23,"-") | K23: On Track | L23: Q1'26A: +45% YoY; Europe +48%
B24: 1 | C24: Free Cash Flow ($M) | D24: Cash | F24: Monthly | G24: 2610 | H24: 2007 | I24: =IFERROR(H24-G24,"-") | J24: =IFERROR(I24/G24,"-") | K24: On Track | L24: Q1'26A: $476M (15%); full-yr cons $2.6B (17.5%)
B25: 2 | C25: FCF Margin | D25: Cash | F25: Monthly | G25: 0.175 | H25: 0.174 | I25: =IFERROR(H25-G25,"-") | J25: =IFERROR(I25/G25,"-") | K25: On Track | L25: Q2'26 guide: mid-teens (MCA reclass headwind)
B26: 2 | C26: Capex % Revenue | D26: Cash | F26: Monthly | G26: 0.017 | H26: 0.017 | I26: =IFERROR(H26-G26,"-") | J26: =IFERROR(I26/G26,"-") | K26: On Track | L26: Lean capex model maintained

Sheet MOIC BRIDGE
B2: MOIC Bridge — Shopify Entry to Exit (FY2028E Base)
B4: Equity value waterfall from entry ($108/share) to exit (FY2028E base). NTB contributions pull from NTB Registry (incremental EV if NTB confirmed). Note: Shopify is a public equity long; MOIC reflects total return, not PE carry.
B6: Component | C6: Equity Value ($M) | D6: MOIC Contribution | E6: Cumulative MOIC
B7: Entry Equity Invested ($108/share × 1,307M) | C7: =INPUTS!C21 | D7: 1 | E7: =IFERROR(INPUTS!C21/INPUTS!C21,"-")
B8: NTB-1: GMV Sustains 25%+ Through FY2027 | C8: =IFERROR('NTB REGISTRY'!F8,"-") | D8: =IFERROR('NTB REGISTRY'!G8,"-") | E8: =IFERROR(E7+D8,"-")
B9: NTB-2: Payments GPV Penetration to 70%+ | C9: =IFERROR('NTB REGISTRY'!F9,"-") | D9: =IFERROR('NTB REGISTRY'!G9,"-") | E9: =IFERROR(E8+D9,"-")
B10: NTB-3: AI Commerce Net Revenue-Positive | C10: =IFERROR('NTB REGISTRY'!F10,"-") | D10: =IFERROR('NTB REGISTRY'!G10,"-") | E10: =IFERROR(E9+D10,"-")
B11: NTB-4: Enterprise Plus Margin Durable | C11: =IFERROR('NTB REGISTRY'!F11,"-") | D11: =IFERROR('NTB REGISTRY'!G11,"-") | E11: =IFERROR(E10+D11,"-")
B12: NTB-5: FCF Margin Expands to 20%+ | C12: =IFERROR('NTB REGISTRY'!F12,"-") | D12: =IFERROR('NTB REGISTRY'!G12,"-") | E12: =IFERROR(E11+D12,"-")
B13: NTB-6: Macro Does Not Materially Deteriorate | C13: =IFERROR('NTB REGISTRY'!F13,"-") | D13: =IFERROR('NTB REGISTRY'!G13,"-") | E13: =IFERROR(E12+D13,"-")
B14: Multiple Re-rating / Compression (net) | E14: =IFERROR(E13+D14,"-")
B16: Exit Proceeds to Equity (FY2028E Base: 45x × $4.49B EBITDA + $8.5B net cash) | C16: =INPUTS!C30 | D16: =IFERROR(INPUTS!C30/INPUTS!C21,"-") | E16: =IFERROR(INPUTS!C30/INPUTS!C21,"-")
